[32mINFO    [0m integration.high_availability.conftest:conftest.py:23 Clearing continuous writes
[32mINFO    [0m integration.high_availability.conftest:conftest.py:26 Starting continuous writes
[32mINFO    [0m integration.helpers:helpers.py:475 Retrieving primary unit
[32mINFO    [0m integration.high_availability.high_availability_helpers:high_availability_helpers.py:361 Ensure continuous writes are incrementing
[32mINFO    [0m integration.helpers:helpers.py:475 Retrieving primary unit
[32mINFO    [0m integration.high_availability.test_self_healing:test_self_healing.py:393 Stopping server on unit mysql/2
[32mINFO    [0m integration.high_availability.test_self_healing:test_self_healing.py:396 Removing data directory
[32mINFO    [0m integration.high_availability.test_self_healing:test_self_healing.py:412 Purge binlogs on unit mysql/0
[32mINFO    [0m integration.high_availability.test_self_healing:test_self_healing.py:412 Purge binlogs on unit mysql/1
[32mINFO    [0m integration.high_availability.test_self_healing:test_self_healing.py:420 Waiting unit to enter in maintenance.
[32mINFO    [0m integration.high_availability.test_self_healing:test_self_healing.py:427 Waiting unit to be back online.
[32mINFO    [0m integration.helpers:helpers.py:475 Retrieving primary unit
[32mINFO    [0m integration.high_availability.test_self_healing:test_self_healing.py:439 Check if instance in cluster
[32mINFO    [0m integration.high_availability.high_availability_helpers:high_availability_helpers.py:361 Ensure continuous writes are incrementing
[32mINFO    [0m integration.helpers:helpers.py:475 Retrieving primary unit
[32mINFO    [0m integration.helpers:helpers.py:475 Retrieving primary unit
[32mINFO    [0m integration.helpers:helpers.py:475 Retrieving primary unit
[32mINFO    [0m integration.high_availability.conftest:conftest.py:31 Clearing continuous writes
[32mINFO    [0m pytest_operator.plugin:plugin.py:790 Model status:

Model  Controller           Cloud/Region         Version  SLA          Timestamp
test   localhost-localhost  localhost/localhost  3.4.3    unsupported  01:48:39Z

App             Version          Status  Scale  Charm           Channel      Rev  Exposed  Message
mysql           8.0.36-0ubun...  active      3  mysql                          0  no       
mysql-test-app  0.0.2            active      1  mysql-test-app  latest/edge   37  no       Last written value=4521

Unit               Workload  Agent  Machine  Public address  Ports           Message
mysql-test-app/0*  active    idle   3        10.40.36.55                     Last written value=4521
mysql/0            active    idle   0        10.40.36.65     3306,33060/tcp  
mysql/1*           active    idle   1        10.40.36.167    3306,33060/tcp  Primary
mysql/2            active    idle   2        10.40.36.148    3306,33060/tcp  

Machine  State    Address       Inst id        Base          AZ  Message
0        started  10.40.36.65   juju-9e213c-0  ubuntu@22.04      Running
1        started  10.40.36.167  juju-9e213c-1  ubuntu@22.04      Running
2        started  10.40.36.148  juju-9e213c-2  ubuntu@22.04      Running
3        started  10.40.36.55   juju-9e213c-3  ubuntu@22.04      Running

[32mINFO    [0m pytest_operator.plugin:plugin.py:796 Juju error logs:

machine-1: 01:30:50 ERROR juju.worker.dependency "kvm-container-provisioner" manifold worker returned unexpected error: container types not yet available
machine-1: 01:30:50 ERROR juju.worker.dependency "lxd-container-provisioner" manifold worker returned unexpected error: container types not yet available
machine-1: 01:30:50 ERROR juju.worker.dependency "broker-tracker" manifold worker returned unexpected error: no container types determined
unit-mysql-1: 01:30:50 ERROR juju.worker.meterstatus error running "meter-status-changed": charm missing from disk
machine-0: 01:30:52 ERROR juju.worker.dependency "lxd-container-provisioner" manifold worker returned unexpected error: container types not yet available
machine-0: 01:30:52 ERROR juju.worker.dependency "broker-tracker" manifold worker returned unexpected error: no container types determined
machine-0: 01:30:52 ERROR juju.worker.dependency "kvm-container-provisioner" manifold worker returned unexpected error: container types not yet available
unit-mysql-0: 01:30:52 ERROR juju.worker.meterstatus error running "meter-status-changed": charm missing from disk
machine-2: 01:31:43 ERROR juju.worker.dependency "kvm-container-provisioner" manifold worker returned unexpected error: container types not yet available
machine-2: 01:31:43 ERROR juju.worker.dependency "lxd-container-provisioner" manifold worker returned unexpected error: container types not yet available
machine-2: 01:31:43 ERROR juju.worker.dependency "broker-tracker" manifold worker returned unexpected error: no container types determined
unit-mysql-2: 01:31:43 ERROR juju.worker.meterstatus error running "meter-status-changed": charm missing from disk
machine-3: 01:34:37 ERROR juju.worker.dependency "broker-tracker" manifold worker returned unexpected error: no container types determined
machine-3: 01:34:37 ERROR juju.worker.dependency "kvm-container-provisioner" manifold worker returned unexpected error: container types not yet available
machine-3: 01:34:37 ERROR juju.worker.dependency "lxd-container-provisioner" manifold worker returned unexpected error: container types not yet available
unit-mysql-test-app-0: 01:34:37 ERROR juju.worker.meterstatus error running "meter-status-changed": charm missing from disk
unit-mysql-0: 01:35:55 ERROR unit.mysql/0.juju-log Failed to get cluster status for test_cluster
unit-mysql-0: 01:36:02 ERROR unit.mysql/0.juju-log Failed to get cluster status for test_cluster
unit-mysql-1: 01:36:04 ERROR unit.mysql/1.juju-log Failed to get cluster status for test_cluster
unit-mysql-1: 01:36:04 ERROR unit.mysql/1.juju-log Failed to get cluster members
Traceback (most recent call last):
  File "/var/lib/juju/agents/unit-mysql-1/charm/src/relations/mysql_provider.py", line 163, in _update_endpoints
    rw_endpoints, ro_endpoints, _ = self.charm._mysql.get_cluster_endpoints()
  File "/var/lib/juju/agents/unit-mysql-1/charm/lib/charms/tempo_k8s/v1/charm_tracing.py", line 544, in wrapped_function
    return callable(*args, **kwargs)  # type: ignore
  File "/var/lib/juju/agents/unit-mysql-1/charm/lib/charms/mysql/v0/mysql.py", line 1946, in get_cluster_endpoints
    raise MySQLGetClusterEndpointsError("Failed to get endpoints from cluster status")
charms.mysql.v0.mysql.MySQLGetClusterEndpointsError: Failed to get endpoints from cluster status
unit-mysql-0: 01:36:11 ERROR unit.mysql/0.juju-log Failed to get cluster status for test_cluster
unit-mysql-1: 01:36:14 ERROR unit.mysql/1.juju-log Failed to get cluster status for test_cluster
unit-mysql-1: 01:36:14 ERROR unit.mysql/1.juju-log Failed to get cluster members
Traceback (most recent call last):
  File "/var/lib/juju/agents/unit-mysql-1/charm/src/relations/mysql_provider.py", line 163, in _update_endpoints
    rw_endpoints, ro_endpoints, _ = self.charm._mysql.get_cluster_endpoints()
  File "/var/lib/juju/agents/unit-mysql-1/charm/lib/charms/tempo_k8s/v1/charm_tracing.py", line 544, in wrapped_function
    return callable(*args, **kwargs)  # type: ignore
  File "/var/lib/juju/agents/unit-mysql-1/charm/lib/charms/mysql/v0/mysql.py", line 1946, in get_cluster_endpoints
    raise MySQLGetClusterEndpointsError("Failed to get endpoints from cluster status")
charms.mysql.v0.mysql.MySQLGetClusterEndpointsError: Failed to get endpoints from cluster status
machine-2: 01:39:13 ERROR juju.worker.dependency "api-caller" manifold worker returned unexpected error: api connection broken unexpectedly
unit-mysql-1: 01:44:08 ERROR unit.mysql/1.juju-log Failed to get cluster status for test_cluster
unit-mysql-1: 01:44:08 ERROR unit.mysql/1.juju-log Failed to get cluster members
Traceback (most recent call last):
  File "/var/lib/juju/agents/unit-mysql-1/charm/src/relations/mysql_provider.py", line 163, in _update_endpoints
    rw_endpoints, ro_endpoints, _ = self.charm._mysql.get_cluster_endpoints()
  File "/var/lib/juju/agents/unit-mysql-1/charm/lib/charms/tempo_k8s/v1/charm_tracing.py", line 544, in wrapped_function
    return callable(*args, **kwargs)  # type: ignore
  File "/var/lib/juju/agents/unit-mysql-1/charm/lib/charms/mysql/v0/mysql.py", line 1946, in get_cluster_endpoints
    raise MySQLGetClusterEndpointsError("Failed to get endpoints from cluster status")
charms.mysql.v0.mysql.MySQLGetClusterEndpointsError: Failed to get endpoints from cluster status
unit-mysql-2: 01:47:04 ERROR unit.mysql/2.juju-log Failed to flush ERROR LOGS logs.
Traceback (most recent call last):
  File "/var/lib/juju/agents/unit-mysql-2/charm/src/mysql_vm_helpers.py", line 685, in _run_mysqlsh_script
    return subprocess.check_output(
  File "/usr/lib/python3.10/subprocess.py", line 421, in check_output
    return run(*popenargs, stdout=PIPE, timeout=timeout, check=True,
  File "/usr/lib/python3.10/subprocess.py", line 526, in run
    raise CalledProcessError(retcode, process.args,
subprocess.CalledProcessError: Command '['charmed-mysql.mysqlsh', '--no-wizard', '--python', '-f', '/var/snap/charmed-mysql/common/tmpg5gp8_rd']' returned non-zero exit status 1.

During handling of the above exception, another exception occurred:

Traceback (most recent call last):
  File "/var/lib/juju/agents/unit-mysql-2/charm/lib/charms/mysql/v0/mysql.py", line 3139, in flush_mysql_logs
    self._run_mysqlsh_script("\n".join(flush_logs_commands), timeout=50)
  File "/var/lib/juju/agents/unit-mysql-2/charm/lib/charms/tempo_k8s/v1/charm_tracing.py", line 544, in wrapped_function
    return callable(*args, **kwargs)  # type: ignore
  File "/var/lib/juju/agents/unit-mysql-2/charm/src/mysql_vm_helpers.py", line 689, in _run_mysqlsh_script
    raise MySQLClientError(e.stderr)
charms.mysql.v0.mysql.MySQLClientError: b'Traceback (most recent call last):\n  File "<string>", line 1, in <module>\nmysqlsh.DBError: MySQL Error (2003): Shell.connect: Can\'t connect to MySQL server on \'juju-9e213c-2.lxd:3306\' (111)\n'
unit-mysql-2: 01:47:06 ERROR unit.mysql/2.juju-log Failed to flush GENERAL LOGS logs.
Traceback (most recent call last):
  File "/var/lib/juju/agents/unit-mysql-2/charm/src/mysql_vm_helpers.py", line 685, in _run_mysqlsh_script
    return subprocess.check_output(
  File "/usr/lib/python3.10/subprocess.py", line 421, in check_output
    return run(*popenargs, stdout=PIPE, timeout=timeout, check=True,
  File "/usr/lib/python3.10/subprocess.py", line 526, in run
    raise CalledProcessError(retcode, process.args,
subprocess.CalledProcessError: Command '['charmed-mysql.mysqlsh', '--no-wizard', '--python', '-f', '/var/snap/charmed-mysql/common/tmpolxznz0c']' returned non-zero exit status 1.

During handling of the above exception, another exception occurred:

Traceback (most recent call last):
  File "/var/lib/juju/agents/unit-mysql-2/charm/lib/charms/mysql/v0/mysql.py", line 3139, in flush_mysql_logs
    self._run_mysqlsh_script("\n".join(flush_logs_commands), timeout=50)
  File "/var/lib/juju/agents/unit-mysql-2/charm/lib/charms/tempo_k8s/v1/charm_tracing.py", line 544, in wrapped_function
    return callable(*args, **kwargs)  # type: ignore
  File "/var/lib/juju/agents/unit-mysql-2/charm/src/mysql_vm_helpers.py", line 689, in _run_mysqlsh_script
    raise MySQLClientError(e.stderr)
charms.mysql.v0.mysql.MySQLClientError: b'Traceback (most recent call last):\n  File "<string>", line 1, in <module>\nmysqlsh.DBError: MySQL Error (2003): Shell.connect: Can\'t connect to MySQL server on \'juju-9e213c-2.lxd:3306\' (111)\n'
unit-mysql-2: 01:47:22 ERROR unit.mysql/2.juju-log Failed to get member state: mysqld daemon is down
unit-mysql-2: 01:47:32 ERROR unit.mysql/2.juju-log Failed to get member state: mysqld daemon is down
unit-mysql-2: 01:47:42 ERROR unit.mysql/2.juju-log Failed to get member state: mysqld daemon is down

[32mINFO    [0m pytest_operator.plugin:plugin.py:862 Forgetting main...