[32mINFO    [0m pytest_operator.plugin:plugin.py:862 Model status:

Model    Controller     Cloud/Region         Version  SLA          Timestamp
testing  concierge-lxd  localhost/localhost  3.6.2    unsupported  01:50:03Z

App             Version          Status  Scale  Charm           Channel      Rev  Exposed  Message
mysql           8.0.41-0ubun...  active      2  mysql                          0  no       
mysql-test-app  0.0.2            error       2  mysql-test-app  latest/edge   65  no       hook failed: "database-relation-changed"

Unit               Workload  Agent      Machine  Public address  Ports           Message
mysql-test-app/0*  error     idle       0        10.235.145.221                  hook failed: "database-relation-changed"
mysql-test-app/1   error     idle       1        10.235.145.174                  hook failed: "database-relation-changed"
mysql/0            active    executing  2        10.235.145.173  3306,33060/tcp  Primary
mysql/4*           active    executing  6        10.235.145.236  3306,33060/tcp  

Machine  State    Address         Inst id        Base          AZ  Message
0        started  10.235.145.221  juju-c474fa-0  ubuntu@22.04      Running
1        started  10.235.145.174  juju-c474fa-1  ubuntu@22.04      Running
2        started  10.235.145.173  juju-c474fa-2  ubuntu@22.04      Running
6        started  10.235.145.236  juju-c474fa-6  ubuntu@22.04      Running

[32mINFO    [0m pytest_operator.plugin:plugin.py:868 Juju error logs:

machine-0: 01:30:55 ERROR juju.worker.dependency "kvm-container-provisioner" manifold worker returned unexpected error: container types not yet available
machine-0: 01:30:55 ERROR juju.worker.dependency "lxd-container-provisioner" manifold worker returned unexpected error: container types not yet available
unit-mysql-test-app-0: 01:30:55 ERROR juju.worker.meterstatus error running "meter-status-changed": charm missing from disk
machine-3: 01:33:22 ERROR juju.worker.dependency "kvm-container-provisioner" manifold worker returned unexpected error: container types not yet available
machine-3: 01:33:22 ERROR juju.worker.dependency "lxd-container-provisioner" manifold worker returned unexpected error: container types not yet available
unit-mysql-1: 01:33:22 ERROR juju.worker.meterstatus error running "meter-status-changed": charm missing from disk
machine-4: 01:33:22 ERROR juju.worker.dependency "lxd-container-provisioner" manifold worker returned unexpected error: container types not yet available
machine-4: 01:33:22 ERROR juju.worker.dependency "kvm-container-provisioner" manifold worker returned unexpected error: container types not yet available
machine-2: 01:33:22 ERROR juju.worker.dependency "lxd-container-provisioner" manifold worker returned unexpected error: container types not yet available
machine-2: 01:33:22 ERROR juju.worker.dependency "kvm-container-provisioner" manifold worker returned unexpected error: container types not yet available
unit-mysql-2: 01:33:23 ERROR juju.worker.meterstatus error running "meter-status-changed": charm missing from disk
unit-mysql-0: 01:33:23 ERROR juju.worker.meterstatus error running "meter-status-changed": charm missing from disk
machine-1: 01:33:23 ERROR juju.worker.dependency "lxd-container-provisioner" manifold worker returned unexpected error: container types not yet available
machine-1: 01:33:23 ERROR juju.worker.dependency "kvm-container-provisioner" manifold worker returned unexpected error: container types not yet available
unit-mysql-test-app-1: 01:33:24 ERROR juju.worker.meterstatus error running "meter-status-changed": charm missing from disk
machine-5: 01:37:43 ERROR juju.worker.dependency "kvm-container-provisioner" manifold worker returned unexpected error: container types not yet available
machine-5: 01:37:43 ERROR juju.worker.dependency "lxd-container-provisioner" manifold worker returned unexpected error: container types not yet available
unit-mysql-3: 01:37:43 ERROR juju.worker.meterstatus error running "meter-status-changed": charm missing from disk
machine-6: 01:42:16 ERROR juju.worker.dependency "kvm-container-provisioner" manifold worker returned unexpected error: container types not yet available
machine-6: 01:42:16 ERROR juju.worker.dependency "lxd-container-provisioner" manifold worker returned unexpected error: container types not yet available
unit-mysql-4: 01:42:16 ERROR juju.worker.meterstatus error running "meter-status-changed": charm missing from disk
unit-mysql-test-app-1: 01:44:44 ERROR unit.mysql-test-app/1.juju-log database:4: Uncaught exception while in charm code:
Traceback (most recent call last):
  File "/var/lib/juju/agents/unit-mysql-test-app-1/charm/venv/lib/python3.10/site-packages/mysql/connector/connection_cext.py", line 611, in cmd_query
    self._cmysql.query(
_mysql_connector.MySQLInterfaceError: Table 'continuous_writes_database.data' doesn't exist

The above exception was the direct cause of the following exception:

Traceback (most recent call last):
  File "/var/lib/juju/agents/unit-mysql-test-app-1/charm/src/charm.py", line 485, in <module>
    main(MySQLTestApplication)
  File "/var/lib/juju/agents/unit-mysql-test-app-1/charm/venv/lib/python3.10/site-packages/ops/main.py", line 40, in main
    return _main.main(charm_class=charm_class, use_juju_for_storage=use_juju_for_storage)
  File "/var/lib/juju/agents/unit-mysql-test-app-1/charm/venv/lib/python3.10/site-packages/ops/_main.py", line 558, in main
    manager.run()
  File "/var/lib/juju/agents/unit-mysql-test-app-1/charm/venv/lib/python3.10/site-packages/ops/_main.py", line 543, in run
    self._emit()
  File "/var/lib/juju/agents/unit-mysql-test-app-1/charm/venv/lib/python3.10/site-packages/ops/_main.py", line 502, in _emit
    self._emit_charm_event(self.dispatcher.event_name)
  File "/var/lib/juju/agents/unit-mysql-test-app-1/charm/venv/lib/python3.10/site-packages/ops/_main.py", line 530, in _emit_charm_event
    event_to_emit.emit(*args, **kwargs)
  File "/var/lib/juju/agents/unit-mysql-test-app-1/charm/venv/lib/python3.10/site-packages/ops/framework.py", line 347, in emit
    framework._emit(event)
  File "/var/lib/juju/agents/unit-mysql-test-app-1/charm/venv/lib/python3.10/site-packages/ops/framework.py", line 906, in _emit
    self._reemit(event_path)
  File "/var/lib/juju/agents/unit-mysql-test-app-1/charm/venv/lib/python3.10/site-packages/ops/framework.py", line 996, in _reemit
    custom_handler(event)
  File "/var/lib/juju/agents/unit-mysql-test-app-1/charm/lib/charms/data_platform_libs/v0/data_interfaces.py", line 3143, in _on_relation_changed_event
    getattr(self.on, "endpoints_changed").emit(
  File "/var/lib/juju/agents/unit-mysql-test-app-1/charm/venv/lib/python3.10/site-packages/ops/framework.py", line 347, in emit
    framework._emit(event)
  File "/var/lib/juju/agents/unit-mysql-test-app-1/charm/venv/lib/python3.10/site-packages/ops/framework.py", line 906, in _emit
    self._reemit(event_path)
  File "/var/lib/juju/agents/unit-mysql-test-app-1/charm/venv/lib/python3.10/site-packages/ops/framework.py", line 996, in _reemit
    custom_handler(event)
  File "/var/lib/juju/agents/unit-mysql-test-app-1/charm/src/charm.py", line 358, in _on_endpoints_changed
    count = self._max_written_value()
  File "/var/lib/juju/agents/unit-mysql-test-app-1/charm/src/charm.py", line 241, in _max_written_value
    cursor.execute(
  File "/var/lib/juju/agents/unit-mysql-test-app-1/charm/venv/lib/python3.10/site-packages/mysql/connector/cursor_cext.py", line 330, in execute
    result = self._cnx.cmd_query(
  File "/var/lib/juju/agents/unit-mysql-test-app-1/charm/venv/lib/python3.10/site-packages/mysql/connector/connection_cext.py", line 619, in cmd_query
    raise get_mysql_exception(
mysql.connector.errors.ProgrammingError: 1146 (42S02): Table 'continuous_writes_database.data' doesn't exist
unit-mysql-test-app-0: 01:44:44 ERROR unit.mysql-test-app/0.juju-log database:4: Uncaught exception while in charm code:
Traceback (most recent call last):
  File "/var/lib/juju/agents/unit-mysql-test-app-0/charm/venv/lib/python3.10/site-packages/mysql/connector/connection_cext.py", line 611, in cmd_query
    self._cmysql.query(
_mysql_connector.MySQLInterfaceError: Table 'continuous_writes_database.data' doesn't exist

The above exception was the direct cause of the following exception:

Traceback (most recent call last):
  File "/var/lib/juju/agents/unit-mysql-test-app-0/charm/src/charm.py", line 485, in <module>
    main(MySQLTestApplication)
  File "/var/lib/juju/agents/unit-mysql-test-app-0/charm/venv/lib/python3.10/site-packages/ops/main.py", line 40, in main
    return _main.main(charm_class=charm_class, use_juju_for_storage=use_juju_for_storage)
  File "/var/lib/juju/agents/unit-mysql-test-app-0/charm/venv/lib/python3.10/site-packages/ops/_main.py", line 558, in main
    manager.run()
  File "/var/lib/juju/agents/unit-mysql-test-app-0/charm/venv/lib/python3.10/site-packages/ops/_main.py", line 543, in run
    self._emit()
  File "/var/lib/juju/agents/unit-mysql-test-app-0/charm/venv/lib/python3.10/site-packages/ops/_main.py", line 502, in _emit
    self._emit_charm_event(self.dispatcher.event_name)
  File "/var/lib/juju/agents/unit-mysql-test-app-0/charm/venv/lib/python3.10/site-packages/ops/_main.py", line 530, in _emit_charm_event
    event_to_emit.emit(*args, **kwargs)
  File "/var/lib/juju/agents/unit-mysql-test-app-0/charm/venv/lib/python3.10/site-packages/ops/framework.py", line 347, in emit
    framework._emit(event)
  File "/var/lib/juju/agents/unit-mysql-test-app-0/charm/venv/lib/python3.10/site-packages/ops/framework.py", line 906, in _emit
    self._reemit(event_path)
  File "/var/lib/juju/agents/unit-mysql-test-app-0/charm/venv/lib/python3.10/site-packages/ops/framework.py", line 996, in _reemit
    custom_handler(event)
  File "/var/lib/juju/agents/unit-mysql-test-app-0/charm/lib/charms/data_platform_libs/v0/data_interfaces.py", line 3143, in _on_relation_changed_event
    getattr(self.on, "endpoints_changed").emit(
  File "/var/lib/juju/agents/unit-mysql-test-app-0/charm/venv/lib/python3.10/site-packages/ops/framework.py", line 347, in emit
    framework._emit(event)
  File "/var/lib/juju/agents/unit-mysql-test-app-0/charm/venv/lib/python3.10/site-packages/ops/framework.py", line 906, in _emit
    self._reemit(event_path)
  File "/var/lib/juju/agents/unit-mysql-test-app-0/charm/venv/lib/python3.10/site-packages/ops/framework.py", line 996, in _reemit
    custom_handler(event)
  File "/var/lib/juju/agents/unit-mysql-test-app-0/charm/src/charm.py", line 358, in _on_endpoints_changed
    count = self._max_written_value()
  File "/var/lib/juju/agents/unit-mysql-test-app-0/charm/src/charm.py", line 241, in _max_written_value
    cursor.execute(
  File "/var/lib/juju/agents/unit-mysql-test-app-0/charm/venv/lib/python3.10/site-packages/mysql/connector/cursor_cext.py", line 330, in execute
    result = self._cnx.cmd_query(
  File "/var/lib/juju/agents/unit-mysql-test-app-0/charm/venv/lib/python3.10/site-packages/mysql/connector/connection_cext.py", line 619, in cmd_query
    raise get_mysql_exception(
mysql.connector.errors.ProgrammingError: 1146 (42S02): Table 'continuous_writes_database.data' doesn't exist
unit-mysql-test-app-1: 01:44:44 ERROR juju.worker.uniter.operation hook "database-relation-changed" (via hook dispatching script: dispatch) failed: exit status 1
unit-mysql-test-app-0: 01:44:45 ERROR juju.worker.uniter.operation hook "database-relation-changed" (via hook dispatching script: dispatch) failed: exit status 1
unit-mysql-test-app-1: 01:44:50 ERROR unit.mysql-test-app/1.juju-log database:4: Uncaught exception while in charm code:
Traceback (most recent call last):
  File "/var/lib/juju/agents/unit-mysql-test-app-1/charm/venv/lib/python3.10/site-packages/mysql/connector/connection_cext.py", line 611, in cmd_query
    self._cmysql.query(
_mysql_connector.MySQLInterfaceError: Table 'continuous_writes_database.data' doesn't exist

The above exception was the direct cause of the following exception:

Traceback (most recent call last):
  File "/var/lib/juju/agents/unit-mysql-test-app-1/charm/src/charm.py", line 485, in <module>
    main(MySQLTestApplication)
  File "/var/lib/juju/agents/unit-mysql-test-app-1/charm/venv/lib/python3.10/site-packages/ops/main.py", line 40, in main
    return _main.main(charm_class=charm_class, use_juju_for_storage=use_juju_for_storage)
  File "/var/lib/juju/agents/unit-mysql-test-app-1/charm/venv/lib/python3.10/site-packages/ops/_main.py", line 558, in main
    manager.run()
  File "/var/lib/juju/agents/unit-mysql-test-app-1/charm/venv/lib/python3.10/site-packages/ops/_main.py", line 543, in run
    self._emit()
  File "/var/lib/juju/agents/unit-mysql-test-app-1/charm/venv/lib/python3.10/site-packages/ops/_main.py", line 502, in _emit
    self._emit_charm_event(self.dispatcher.event_name)
  File "/var/lib/juju/agents/unit-mysql-test-app-1/charm/venv/lib/python3.10/site-packages/ops/_main.py", line 530, in _emit_charm_event
    event_to_emit.emit(*args, **kwargs)
  File "/var/lib/juju/agents/unit-mysql-test-app-1/charm/venv/lib/python3.10/site-packages/ops/framework.py", line 347, in emit
    framework._emit(event)
  File "/var/lib/juju/agents/unit-mysql-test-app-1/charm/venv/lib/python3.10/site-packages/ops/framework.py", line 906, in _emit
    self._reemit(event_path)
  File "/var/lib/juju/agents/unit-mysql-test-app-1/charm/venv/lib/python3.10/site-packages/ops/framework.py", line 996, in _reemit
    custom_handler(event)
  File "/var/lib/juju/agents/unit-mysql-test-app-1/charm/lib/charms/data_platform_libs/v0/data_interfaces.py", line 3143, in _on_relation_changed_event
    getattr(self.on, "endpoints_changed").emit(
  File "/var/lib/juju/agents/unit-mysql-test-app-1/charm/venv/lib/python3.10/site-packages/ops/framework.py", line 347, in emit
    framework._emit(event)
  File "/var/lib/juju/agents/unit-mysql-test-app-1/charm/venv/lib/python3.10/site-packages/ops/framework.py", line 906, in _emit
    self._reemit(event_path)
  File "/var/lib/juju/agents/unit-mysql-test-app-1/charm/venv/lib/python3.10/site-packages/ops/framework.py", line 996, in _reemit
    custom_handler(event)
  File "/var/lib/juju/agents/unit-mysql-test-app-1/charm/src/charm.py", line 358, in _on_endpoints_changed
    count = self._max_written_value()
  File "/var/lib/juju/agents/unit-mysql-test-app-1/charm/src/charm.py", line 241, in _max_written_value
    cursor.execute(
  File "/var/lib/juju/agents/unit-mysql-test-app-1/charm/venv/lib/python3.10/site-packages/mysql/connector/cursor_cext.py", line 330, in execute
    result = self._cnx.cmd_query(
  File "/var/lib/juju/agents/unit-mysql-test-app-1/charm/venv/lib/python3.10/site-packages/mysql/connector/connection_cext.py", line 619, in cmd_query
    raise get_mysql_exception(
mysql.connector.errors.ProgrammingError: 1146 (42S02): Table 'continuous_writes_database.data' doesn't exist
unit-mysql-test-app-0: 01:44:50 ERROR unit.mysql-test-app/0.juju-log database:4: Uncaught exception while in charm code:
Traceback (most recent call last):
  File "/var/lib/juju/agents/unit-mysql-test-app-0/charm/venv/lib/python3.10/site-packages/mysql/connector/connection_cext.py", line 611, in cmd_query
    self._cmysql.query(
_mysql_connector.MySQLInterfaceError: Table 'continuous_writes_database.data' doesn't exist

The above exception was the direct cause of the following exception:

Traceback (most recent call last):
  File "/var/lib/juju/agents/unit-mysql-test-app-0/charm/src/charm.py", line 485, in <module>
    main(MySQLTestApplication)
  File "/var/lib/juju/agents/unit-mysql-test-app-0/charm/venv/lib/python3.10/site-packages/ops/main.py", line 40, in main
    return _main.main(charm_class=charm_class, use_juju_for_storage=use_juju_for_storage)
  File "/var/lib/juju/agents/unit-mysql-test-app-0/charm/venv/lib/python3.10/site-packages/ops/_main.py", line 558, in main
    manager.run()
  File "/var/lib/juju/agents/unit-mysql-test-app-0/charm/venv/lib/python3.10/site-packages/ops/_main.py", line 543, in run
    self._emit()
  File "/var/lib/juju/agents/unit-mysql-test-app-0/charm/venv/lib/python3.10/site-packages/ops/_main.py", line 502, in _emit
    self._emit_charm_event(self.dispatcher.event_name)
  File "/var/lib/juju/agents/unit-mysql-test-app-0/charm/venv/lib/python3.10/site-packages/ops/_main.py", line 530, in _emit_charm_event
    event_to_emit.emit(*args, **kwargs)
  File "/var/lib/juju/agents/unit-mysql-test-app-0/charm/venv/lib/python3.10/site-packages/ops/framework.py", line 347, in emit
    framework._emit(event)
  File "/var/lib/juju/agents/unit-mysql-test-app-0/charm/venv/lib/python3.10/site-packages/ops/framework.py", line 906, in _emit
    self._reemit(event_path)
  File "/var/lib/juju/agents/unit-mysql-test-app-0/charm/venv/lib/python3.10/site-packages/ops/framework.py", line 996, in _reemit
    custom_handler(event)
  File "/var/lib/juju/agents/unit-mysql-test-app-0/charm/lib/charms/data_platform_libs/v0/data_interfaces.py", line 3143, in _on_relation_changed_event
    getattr(self.on, "endpoints_changed").emit(
  File "/var/lib/juju/agents/unit-mysql-test-app-0/charm/venv/lib/python3.10/site-packages/ops/framework.py", line 347, in emit
    framework._emit(event)
  File "/var/lib/juju/agents/unit-mysql-test-app-0/charm/venv/lib/python3.10/site-packages/ops/framework.py", line 906, in _emit
    self._reemit(event_path)
  File "/var/lib/juju/agents/unit-mysql-test-app-0/charm/venv/lib/python3.10/site-packages/ops/framework.py", line 996, in _reemit
    custom_handler(event)
  File "/var/lib/juju/agents/unit-mysql-test-app-0/charm/src/charm.py", line 358, in _on_endpoints_changed
    count = self._max_written_value()
  File "/var/lib/juju/agents/unit-mysql-test-app-0/charm/src/charm.py", line 241, in _max_written_value
    cursor.execute(
  File "/var/lib/juju/agents/unit-mysql-test-app-0/charm/venv/lib/python3.10/site-packages/mysql/connector/cursor_cext.py", line 330, in execute
    result = self._cnx.cmd_query(
  File "/var/lib/juju/agents/unit-mysql-test-app-0/charm/venv/lib/python3.10/site-packages/mysql/connector/connection_cext.py", line 619, in cmd_query
    raise get_mysql_exception(
mysql.connector.errors.ProgrammingError: 1146 (42S02): Table 'continuous_writes_database.data' doesn't exist
unit-mysql-test-app-1: 01:44:50 ERROR juju.worker.uniter.operation hook "database-relation-changed" (via hook dispatching script: dispatch) failed: exit status 1
unit-mysql-test-app-0: 01:44:50 ERROR juju.worker.uniter.operation hook "database-relation-changed" (via hook dispatching script: dispatch) failed: exit status 1
unit-mysql-test-app-0: 01:45:00 ERROR unit.mysql-test-app/0.juju-log database:4: Uncaught exception while in charm code:
Traceback (most recent call last):
  File "/var/lib/juju/agents/unit-mysql-test-app-0/charm/venv/lib/python3.10/site-packages/mysql/connector/connection_cext.py", line 611, in cmd_query
    self._cmysql.query(
_mysql_connector.MySQLInterfaceError: Table 'continuous_writes_database.data' doesn't exist

The above exception was the direct cause of the following exception:

Traceback (most recent call last):
  File "/var/lib/juju/agents/unit-mysql-test-app-0/charm/src/charm.py", line 485, in <module>
    main(MySQLTestApplication)
  File "/var/lib/juju/agents/unit-mysql-test-app-0/charm/venv/lib/python3.10/site-packages/ops/main.py", line 40, in main
    return _main.main(charm_class=charm_class, use_juju_for_storage=use_juju_for_storage)
  File "/var/lib/juju/agents/unit-mysql-test-app-0/charm/venv/lib/python3.10/site-packages/ops/_main.py", line 558, in main
    manager.run()
  File "/var/lib/juju/agents/unit-mysql-test-app-0/charm/venv/lib/python3.10/site-packages/ops/_main.py", line 543, in run
    self._emit()
  File "/var/lib/juju/agents/unit-mysql-test-app-0/charm/venv/lib/python3.10/site-packages/ops/_main.py", line 502, in _emit
    self._emit_charm_event(self.dispatcher.event_name)
  File "/var/lib/juju/agents/unit-mysql-test-app-0/charm/venv/lib/python3.10/site-packages/ops/_main.py", line 530, in _emit_charm_event
    event_to_emit.emit(*args, **kwargs)
  File "/var/lib/juju/agents/unit-mysql-test-app-0/charm/venv/lib/python3.10/site-packages/ops/framework.py", line 347, in emit
    framework._emit(event)
  File "/var/lib/juju/agents/unit-mysql-test-app-0/charm/venv/lib/python3.10/site-packages/ops/framework.py", line 906, in _emit
    self._reemit(event_path)
  File "/var/lib/juju/agents/unit-mysql-test-app-0/charm/venv/lib/python3.10/site-packages/ops/framework.py", line 996, in _reemit
    custom_handler(event)
  File "/var/lib/juju/agents/unit-mysql-test-app-0/charm/lib/charms/data_platform_libs/v0/data_interfaces.py", line 3143, in _on_relation_changed_event
    getattr(self.on, "endpoints_changed").emit(
  File "/var/lib/juju/agents/unit-mysql-test-app-0/charm/venv/lib/python3.10/site-packages/ops/framework.py", line 347, in emit
    framework._emit(event)
  File "/var/lib/juju/agents/unit-mysql-test-app-0/charm/venv/lib/python3.10/site-packages/ops/framework.py", line 906, in _emit
    self._reemit(event_path)
  File "/var/lib/juju/agents/unit-mysql-test-app-0/charm/venv/lib/python3.10/site-packages/ops/framework.py", line 996, in _reemit
    custom_handler(event)
  File "/var/lib/juju/agents/unit-mysql-test-app-0/charm/src/charm.py", line 358, in _on_endpoints_changed
    count = self._max_written_value()
  File "/var/lib/juju/agents/unit-mysql-test-app-0/charm/src/charm.py", line 241, in _max_written_value
    cursor.execute(
  File "/var/lib/juju/agents/unit-mysql-test-app-0/charm/venv/lib/python3.10/site-packages/mysql/connector/cursor_cext.py", line 330, in execute
    result = self._cnx.cmd_query(
  File "/var/lib/juju/agents/unit-mysql-test-app-0/charm/venv/lib/python3.10/site-packages/mysql/connector/connection_cext.py", line 619, in cmd_query
    raise get_mysql_exception(
mysql.connector.errors.ProgrammingError: 1146 (42S02): Table 'continuous_writes_database.data' doesn't exist
unit-mysql-test-app-1: 01:45:00 ERROR unit.mysql-test-app/1.juju-log database:4: Uncaught exception while in charm code:
Traceback (most recent call last):
  File "/var/lib/juju/agents/unit-mysql-test-app-1/charm/venv/lib/python3.10/site-packages/mysql/connector/connection_cext.py", line 611, in cmd_query
    self._cmysql.query(
_mysql_connector.MySQLInterfaceError: Table 'continuous_writes_database.data' doesn't exist

The above exception was the direct cause of the following exception:

Traceback (most recent call last):
  File "/var/lib/juju/agents/unit-mysql-test-app-1/charm/src/charm.py", line 485, in <module>
    main(MySQLTestApplication)
  File "/var/lib/juju/agents/unit-mysql-test-app-1/charm/venv/lib/python3.10/site-packages/ops/main.py", line 40, in main
    return _main.main(charm_class=charm_class, use_juju_for_storage=use_juju_for_storage)
  File "/var/lib/juju/agents/unit-mysql-test-app-1/charm/venv/lib/python3.10/site-packages/ops/_main.py", line 558, in main
    manager.run()
  File "/var/lib/juju/agents/unit-mysql-test-app-1/charm/venv/lib/python3.10/site-packages/ops/_main.py", line 543, in run
    self._emit()
  File "/var/lib/juju/agents/unit-mysql-test-app-1/charm/venv/lib/python3.10/site-packages/ops/_main.py", line 502, in _emit
    self._emit_charm_event(self.dispatcher.event_name)
  File "/var/lib/juju/agents/unit-mysql-test-app-1/charm/venv/lib/python3.10/site-packages/ops/_main.py", line 530, in _emit_charm_event
    event_to_emit.emit(*args, **kwargs)
  File "/var/lib/juju/agents/unit-mysql-test-app-1/charm/venv/lib/python3.10/site-packages/ops/framework.py", line 347, in emit
    framework._emit(event)
  File "/var/lib/juju/agents/unit-mysql-test-app-1/charm/venv/lib/python3.10/site-packages/ops/framework.py", line 906, in _emit
    self._reemit(event_path)
  File "/var/lib/juju/agents/unit-mysql-test-app-1/charm/venv/lib/python3.10/site-packages/ops/framework.py", line 996, in _reemit
    custom_handler(event)
  File "/var/lib/juju/agents/unit-mysql-test-app-1/charm/lib/charms/data_platform_libs/v0/data_interfaces.py", line 3143, in _on_relation_changed_event
    getattr(self.on, "endpoints_changed").emit(
  File "/var/lib/juju/agents/unit-mysql-test-app-1/charm/venv/lib/python3.10/site-packages/ops/framework.py", line 347, in emit
    framework._emit(event)
  File "/var/lib/juju/agents/unit-mysql-test-app-1/charm/venv/lib/python3.10/site-packages/ops/framework.py", line 906, in _emit
    self._reemit(event_path)
  File "/var/lib/juju/agents/unit-mysql-test-app-1/charm/venv/lib/python3.10/site-packages/ops/framework.py", line 996, in _reemit
    custom_handler(event)
  File "/var/lib/juju/agents/unit-mysql-test-app-1/charm/src/charm.py", line 358, in _on_endpoints_changed
    count = self._max_written_value()
  File "/var/lib/juju/agents/unit-mysql-test-app-1/charm/src/charm.py", line 241, in _max_written_value
    cursor.execute(
  File "/var/lib/juju/agents/unit-mysql-test-app-1/charm/venv/lib/python3.10/site-packages/mysql/connector/cursor_cext.py", line 330, in execute
    result = self._cnx.cmd_query(
  File "/var/lib/juju/agents/unit-mysql-test-app-1/charm/venv/lib/python3.10/site-packages/mysql/connector/connection_cext.py", line 619, in cmd_query
    raise get_mysql_exception(
mysql.connector.errors.ProgrammingError: 1146 (42S02): Table 'continuous_writes_database.data' doesn't exist
unit-mysql-test-app-0: 01:45:01 ERROR juju.worker.uniter.operation hook "database-relation-changed" (via hook dispatching script: dispatch) failed: exit status 1
unit-mysql-test-app-1: 01:45:01 ERROR juju.worker.uniter.operation hook "database-relation-changed" (via hook dispatching script: dispatch) failed: exit status 1
unit-mysql-test-app-0: 01:45:21 ERROR unit.mysql-test-app/0.juju-log database:4: Uncaught exception while in charm code:
Traceback (most recent call last):
  File "/var/lib/juju/agents/unit-mysql-test-app-0/charm/venv/lib/python3.10/site-packages/mysql/connector/connection_cext.py", line 611, in cmd_query
    self._cmysql.query(
_mysql_connector.MySQLInterfaceError: Table 'continuous_writes_database.data' doesn't exist

The above exception was the direct cause of the following exception:

Traceback (most recent call last):
  File "/var/lib/juju/agents/unit-mysql-test-app-0/charm/src/charm.py", line 485, in <module>
    main(MySQLTestApplication)
  File "/var/lib/juju/agents/unit-mysql-test-app-0/charm/venv/lib/python3.10/site-packages/ops/main.py", line 40, in main
    return _main.main(charm_class=charm_class, use_juju_for_storage=use_juju_for_storage)
  File "/var/lib/juju/agents/unit-mysql-test-app-0/charm/venv/lib/python3.10/site-packages/ops/_main.py", line 558, in main
    manager.run()
  File "/var/lib/juju/agents/unit-mysql-test-app-0/charm/venv/lib/python3.10/site-packages/ops/_main.py", line 543, in run
    self._emit()
  File "/var/lib/juju/agents/unit-mysql-test-app-0/charm/venv/lib/python3.10/site-packages/ops/_main.py", line 502, in _emit
    self._emit_charm_event(self.dispatcher.event_name)
  File "/var/lib/juju/agents/unit-mysql-test-app-0/charm/venv/lib/python3.10/site-packages/ops/_main.py", line 530, in _emit_charm_event
    event_to_emit.emit(*args, **kwargs)
  File "/var/lib/juju/agents/unit-mysql-test-app-0/charm/venv/lib/python3.10/site-packages/ops/framework.py", line 347, in emit
    framework._emit(event)
  File "/var/lib/juju/agents/unit-mysql-test-app-0/charm/venv/lib/python3.10/site-packages/ops/framework.py", line 906, in _emit
    self._reemit(event_path)
  File "/var/lib/juju/agents/unit-mysql-test-app-0/charm/venv/lib/python3.10/site-packages/ops/framework.py", line 996, in _reemit
    custom_handler(event)
  File "/var/lib/juju/agents/unit-mysql-test-app-0/charm/lib/charms/data_platform_libs/v0/data_interfaces.py", line 3143, in _on_relation_changed_event
    getattr(self.on, "endpoints_changed").emit(
  File "/var/lib/juju/agents/unit-mysql-test-app-0/charm/venv/lib/python3.10/site-packages/ops/framework.py", line 347, in emit
    framework._emit(event)
  File "/var/lib/juju/agents/unit-mysql-test-app-0/charm/venv/lib/python3.10/site-packages/ops/framework.py", line 906, in _emit
    self._reemit(event_path)
  File "/var/lib/juju/agents/unit-mysql-test-app-0/charm/venv/lib/python3.10/site-packages/ops/framework.py", line 996, in _reemit
    custom_handler(event)
  File "/var/lib/juju/agents/unit-mysql-test-app-0/charm/src/charm.py", line 358, in _on_endpoints_changed
    count = self._max_written_value()
  File "/var/lib/juju/agents/unit-mysql-test-app-0/charm/src/charm.py", line 241, in _max_written_value
    cursor.execute(
  File "/var/lib/juju/agents/unit-mysql-test-app-0/charm/venv/lib/python3.10/site-packages/mysql/connector/cursor_cext.py", line 330, in execute
    result = self._cnx.cmd_query(
  File "/var/lib/juju/agents/unit-mysql-test-app-0/charm/venv/lib/python3.10/site-packages/mysql/connector/connection_cext.py", line 619, in cmd_query
    raise get_mysql_exception(
mysql.connector.errors.ProgrammingError: 1146 (42S02): Table 'continuous_writes_database.data' doesn't exist
unit-mysql-test-app-1: 01:45:21 ERROR unit.mysql-test-app/1.juju-log database:4: Uncaught exception while in charm code:
Traceback (most recent call last):
  File "/var/lib/juju/agents/unit-mysql-test-app-1/charm/venv/lib/python3.10/site-packages/mysql/connector/connection_cext.py", line 611, in cmd_query
    self._cmysql.query(
_mysql_connector.MySQLInterfaceError: Table 'continuous_writes_database.data' doesn't exist

The above exception was the direct cause of the following exception:

Traceback (most recent call last):
  File "/var/lib/juju/agents/unit-mysql-test-app-1/charm/src/charm.py", line 485, in <module>
    main(MySQLTestApplication)
  File "/var/lib/juju/agents/unit-mysql-test-app-1/charm/venv/lib/python3.10/site-packages/ops/main.py", line 40, in main
    return _main.main(charm_class=charm_class, use_juju_for_storage=use_juju_for_storage)
  File "/var/lib/juju/agents/unit-mysql-test-app-1/charm/venv/lib/python3.10/site-packages/ops/_main.py", line 558, in main
    manager.run()
  File "/var/lib/juju/agents/unit-mysql-test-app-1/charm/venv/lib/python3.10/site-packages/ops/_main.py", line 543, in run
    self._emit()
  File "/var/lib/juju/agents/unit-mysql-test-app-1/charm/venv/lib/python3.10/site-packages/ops/_main.py", line 502, in _emit
    self._emit_charm_event(self.dispatcher.event_name)
  File "/var/lib/juju/agents/unit-mysql-test-app-1/charm/venv/lib/python3.10/site-packages/ops/_main.py", line 530, in _emit_charm_event
    event_to_emit.emit(*args, **kwargs)
  File "/var/lib/juju/agents/unit-mysql-test-app-1/charm/venv/lib/python3.10/site-packages/ops/framework.py", line 347, in emit
    framework._emit(event)
  File "/var/lib/juju/agents/unit-mysql-test-app-1/charm/venv/lib/python3.10/site-packages/ops/framework.py", line 906, in _emit
    self._reemit(event_path)
  File "/var/lib/juju/agents/unit-mysql-test-app-1/charm/venv/lib/python3.10/site-packages/ops/framework.py", line 996, in _reemit
    custom_handler(event)
  File "/var/lib/juju/agents/unit-mysql-test-app-1/charm/lib/charms/data_platform_libs/v0/data_interfaces.py", line 3143, in _on_relation_changed_event
    getattr(self.on, "endpoints_changed").emit(
  File "/var/lib/juju/agents/unit-mysql-test-app-1/charm/venv/lib/python3.10/site-packages/ops/framework.py", line 347, in emit
    framework._emit(event)
  File "/var/lib/juju/agents/unit-mysql-test-app-1/charm/venv/lib/python3.10/site-packages/ops/framework.py", line 906, in _emit
    self._reemit(event_path)
  File "/var/lib/juju/agents/unit-mysql-test-app-1/charm/venv/lib/python3.10/site-packages/ops/framework.py", line 996, in _reemit
    custom_handler(event)
  File "/var/lib/juju/agents/unit-mysql-test-app-1/charm/src/charm.py", line 358, in _on_endpoints_changed
    count = self._max_written_value()
  File "/var/lib/juju/agents/unit-mysql-test-app-1/charm/src/charm.py", line 241, in _max_written_value
    cursor.execute(
  File "/var/lib/juju/agents/unit-mysql-test-app-1/charm/venv/lib/python3.10/site-packages/mysql/connector/cursor_cext.py", line 330, in execute
    result = self._cnx.cmd_query(
  File "/var/lib/juju/agents/unit-mysql-test-app-1/charm/venv/lib/python3.10/site-packages/mysql/connector/connection_cext.py", line 619, in cmd_query
    raise get_mysql_exception(
mysql.connector.errors.ProgrammingError: 1146 (42S02): Table 'continuous_writes_database.data' doesn't exist
unit-mysql-test-app-0: 01:45:21 ERROR juju.worker.uniter.operation hook "database-relation-changed" (via hook dispatching script: dispatch) failed: exit status 1
unit-mysql-test-app-1: 01:45:21 ERROR juju.worker.uniter.operation hook "database-relation-changed" (via hook dispatching script: dispatch) failed: exit status 1
unit-mysql-test-app-0: 01:45:59 ERROR unit.mysql-test-app/0.juju-log database:4: Uncaught exception while in charm code:
Traceback (most recent call last):
  File "/var/lib/juju/agents/unit-mysql-test-app-0/charm/venv/lib/python3.10/site-packages/mysql/connector/connection_cext.py", line 611, in cmd_query
    self._cmysql.query(
_mysql_connector.MySQLInterfaceError: Table 'continuous_writes_database.data' doesn't exist

The above exception was the direct cause of the following exception:

Traceback (most recent call last):
  File "/var/lib/juju/agents/unit-mysql-test-app-0/charm/src/charm.py", line 485, in <module>
    main(MySQLTestApplication)
  File "/var/lib/juju/agents/unit-mysql-test-app-0/charm/venv/lib/python3.10/site-packages/ops/main.py", line 40, in main
    return _main.main(charm_class=charm_class, use_juju_for_storage=use_juju_for_storage)
  File "/var/lib/juju/agents/unit-mysql-test-app-0/charm/venv/lib/python3.10/site-packages/ops/_main.py", line 558, in main
    manager.run()
  File "/var/lib/juju/agents/unit-mysql-test-app-0/charm/venv/lib/python3.10/site-packages/ops/_main.py", line 543, in run
    self._emit()
  File "/var/lib/juju/agents/unit-mysql-test-app-0/charm/venv/lib/python3.10/site-packages/ops/_main.py", line 502, in _emit
    self._emit_charm_event(self.dispatcher.event_name)
  File "/var/lib/juju/agents/unit-mysql-test-app-0/charm/venv/lib/python3.10/site-packages/ops/_main.py", line 530, in _emit_charm_event
    event_to_emit.emit(*args, **kwargs)
  File "/var/lib/juju/agents/unit-mysql-test-app-0/charm/venv/lib/python3.10/site-packages/ops/framework.py", line 347, in emit
    framework._emit(event)
  File "/var/lib/juju/agents/unit-mysql-test-app-0/charm/venv/lib/python3.10/site-packages/ops/framework.py", line 906, in _emit
    self._reemit(event_path)
  File "/var/lib/juju/agents/unit-mysql-test-app-0/charm/venv/lib/python3.10/site-packages/ops/framework.py", line 996, in _reemit
    custom_handler(event)
  File "/var/lib/juju/agents/unit-mysql-test-app-0/charm/lib/charms/data_platform_libs/v0/data_interfaces.py", line 3143, in _on_relation_changed_event
    getattr(self.on, "endpoints_changed").emit(
  File "/var/lib/juju/agents/unit-mysql-test-app-0/charm/venv/lib/python3.10/site-packages/ops/framework.py", line 347, in emit
    framework._emit(event)
  File "/var/lib/juju/agents/unit-mysql-test-app-0/charm/venv/lib/python3.10/site-packages/ops/framework.py", line 906, in _emit
    self._reemit(event_path)
  File "/var/lib/juju/agents/unit-mysql-test-app-0/charm/venv/lib/python3.10/site-packages/ops/framework.py", line 996, in _reemit
    custom_handler(event)
  File "/var/lib/juju/agents/unit-mysql-test-app-0/charm/src/charm.py", line 358, in _on_endpoints_changed
    count = self._max_written_value()
  File "/var/lib/juju/agents/unit-mysql-test-app-0/charm/src/charm.py", line 241, in _max_written_value
    cursor.execute(
  File "/var/lib/juju/agents/unit-mysql-test-app-0/charm/venv/lib/python3.10/site-packages/mysql/connector/cursor_cext.py", line 330, in execute
    result = self._cnx.cmd_query(
  File "/var/lib/juju/agents/unit-mysql-test-app-0/charm/venv/lib/python3.10/site-packages/mysql/connector/connection_cext.py", line 619, in cmd_query
    raise get_mysql_exception(
mysql.connector.errors.ProgrammingError: 1146 (42S02): Table 'continuous_writes_database.data' doesn't exist
unit-mysql-test-app-0: 01:45:59 ERROR juju.worker.uniter.operation hook "database-relation-changed" (via hook dispatching script: dispatch) failed: exit status 1
unit-mysql-test-app-1: 01:46:01 ERROR unit.mysql-test-app/1.juju-log database:4: Uncaught exception while in charm code:
Traceback (most recent call last):
  File "/var/lib/juju/agents/unit-mysql-test-app-1/charm/venv/lib/python3.10/site-packages/mysql/connector/connection_cext.py", line 611, in cmd_query
    self._cmysql.query(
_mysql_connector.MySQLInterfaceError: Table 'continuous_writes_database.data' doesn't exist

The above exception was the direct cause of the following exception:

Traceback (most recent call last):
  File "/var/lib/juju/agents/unit-mysql-test-app-1/charm/src/charm.py", line 485, in <module>
    main(MySQLTestApplication)
  File "/var/lib/juju/agents/unit-mysql-test-app-1/charm/venv/lib/python3.10/site-packages/ops/main.py", line 40, in main
    return _main.main(charm_class=charm_class, use_juju_for_storage=use_juju_for_storage)
  File "/var/lib/juju/agents/unit-mysql-test-app-1/charm/venv/lib/python3.10/site-packages/ops/_main.py", line 558, in main
    manager.run()
  File "/var/lib/juju/agents/unit-mysql-test-app-1/charm/venv/lib/python3.10/site-packages/ops/_main.py", line 543, in run
    self._emit()
  File "/var/lib/juju/agents/unit-mysql-test-app-1/charm/venv/lib/python3.10/site-packages/ops/_main.py", line 502, in _emit
    self._emit_charm_event(self.dispatcher.event_name)
  File "/var/lib/juju/agents/unit-mysql-test-app-1/charm/venv/lib/python3.10/site-packages/ops/_main.py", line 530, in _emit_charm_event
    event_to_emit.emit(*args, **kwargs)
  File "/var/lib/juju/agents/unit-mysql-test-app-1/charm/venv/lib/python3.10/site-packages/ops/framework.py", line 347, in emit
    framework._emit(event)
  File "/var/lib/juju/agents/unit-mysql-test-app-1/charm/venv/lib/python3.10/site-packages/ops/framework.py", line 906, in _emit
    self._reemit(event_path)
  File "/var/lib/juju/agents/unit-mysql-test-app-1/charm/venv/lib/python3.10/site-packages/ops/framework.py", line 996, in _reemit
    custom_handler(event)
  File "/var/lib/juju/agents/unit-mysql-test-app-1/charm/lib/charms/data_platform_libs/v0/data_interfaces.py", line 3143, in _on_relation_changed_event
    getattr(self.on, "endpoints_changed").emit(
  File "/var/lib/juju/agents/unit-mysql-test-app-1/charm/venv/lib/python3.10/site-packages/ops/framework.py", line 347, in emit
    framework._emit(event)
  File "/var/lib/juju/agents/unit-mysql-test-app-1/charm/venv/lib/python3.10/site-packages/ops/framework.py", line 906, in _emit
    self._reemit(event_path)
  File "/var/lib/juju/agents/unit-mysql-test-app-1/charm/venv/lib/python3.10/site-packages/ops/framework.py", line 996, in _reemit
    custom_handler(event)
  File "/var/lib/juju/agents/unit-mysql-test-app-1/charm/src/charm.py", line 358, in _on_endpoints_changed
    count = self._max_written_value()
  File "/var/lib/juju/agents/unit-mysql-test-app-1/charm/src/charm.py", line 241, in _max_written_value
    cursor.execute(
  File "/var/lib/juju/agents/unit-mysql-test-app-1/charm/venv/lib/python3.10/site-packages/mysql/connector/cursor_cext.py", line 330, in execute
    result = self._cnx.cmd_query(
  File "/var/lib/juju/agents/unit-mysql-test-app-1/charm/venv/lib/python3.10/site-packages/mysql/connector/connection_cext.py", line 619, in cmd_query
    raise get_mysql_exception(
mysql.connector.errors.ProgrammingError: 1146 (42S02): Table 'continuous_writes_database.data' doesn't exist
unit-mysql-test-app-1: 01:46:01 ERROR juju.worker.uniter.operation hook "database-relation-changed" (via hook dispatching script: dispatch) failed: exit status 1
unit-mysql-test-app-0: 01:47:18 ERROR unit.mysql-test-app/0.juju-log database:4: Uncaught exception while in charm code:
Traceback (most recent call last):
  File "/var/lib/juju/agents/unit-mysql-test-app-0/charm/venv/lib/python3.10/site-packages/mysql/connector/connection_cext.py", line 611, in cmd_query
    self._cmysql.query(
_mysql_connector.MySQLInterfaceError: Table 'continuous_writes_database.data' doesn't exist

The above exception was the direct cause of the following exception:

Traceback (most recent call last):
  File "/var/lib/juju/agents/unit-mysql-test-app-0/charm/src/charm.py", line 485, in <module>
    main(MySQLTestApplication)
  File "/var/lib/juju/agents/unit-mysql-test-app-0/charm/venv/lib/python3.10/site-packages/ops/main.py", line 40, in main
    return _main.main(charm_class=charm_class, use_juju_for_storage=use_juju_for_storage)
  File "/var/lib/juju/agents/unit-mysql-test-app-0/charm/venv/lib/python3.10/site-packages/ops/_main.py", line 558, in main
    manager.run()
  File "/var/lib/juju/agents/unit-mysql-test-app-0/charm/venv/lib/python3.10/site-packages/ops/_main.py", line 543, in run
    self._emit()
  File "/var/lib/juju/agents/unit-mysql-test-app-0/charm/venv/lib/python3.10/site-packages/ops/_main.py", line 502, in _emit
    self._emit_charm_event(self.dispatcher.event_name)
  File "/var/lib/juju/agents/unit-mysql-test-app-0/charm/venv/lib/python3.10/site-packages/ops/_main.py", line 530, in _emit_charm_event
    event_to_emit.emit(*args, **kwargs)
  File "/var/lib/juju/agents/unit-mysql-test-app-0/charm/venv/lib/python3.10/site-packages/ops/framework.py", line 347, in emit
    framework._emit(event)
  File "/var/lib/juju/agents/unit-mysql-test-app-0/charm/venv/lib/python3.10/site-packages/ops/framework.py", line 906, in _emit
    self._reemit(event_path)
  File "/var/lib/juju/agents/unit-mysql-test-app-0/charm/venv/lib/python3.10/site-packages/ops/framework.py", line 996, in _reemit
    custom_handler(event)
  File "/var/lib/juju/agents/unit-mysql-test-app-0/charm/lib/charms/data_platform_libs/v0/data_interfaces.py", line 3143, in _on_relation_changed_event
    getattr(self.on, "endpoints_changed").emit(
  File "/var/lib/juju/agents/unit-mysql-test-app-0/charm/venv/lib/python3.10/site-packages/ops/framework.py", line 347, in emit
    framework._emit(event)
  File "/var/lib/juju/agents/unit-mysql-test-app-0/charm/venv/lib/python3.10/site-packages/ops/framework.py", line 906, in _emit
    self._reemit(event_path)
  File "/var/lib/juju/agents/unit-mysql-test-app-0/charm/venv/lib/python3.10/site-packages/ops/framework.py", line 996, in _reemit
    custom_handler(event)
  File "/var/lib/juju/agents/unit-mysql-test-app-0/charm/src/charm.py", line 358, in _on_endpoints_changed
    count = self._max_written_value()
  File "/var/lib/juju/agents/unit-mysql-test-app-0/charm/src/charm.py", line 241, in _max_written_value
    cursor.execute(
  File "/var/lib/juju/agents/unit-mysql-test-app-0/charm/venv/lib/python3.10/site-packages/mysql/connector/cursor_cext.py", line 330, in execute
    result = self._cnx.cmd_query(
  File "/var/lib/juju/agents/unit-mysql-test-app-0/charm/venv/lib/python3.10/site-packages/mysql/connector/connection_cext.py", line 619, in cmd_query
    raise get_mysql_exception(
mysql.connector.errors.ProgrammingError: 1146 (42S02): Table 'continuous_writes_database.data' doesn't exist
unit-mysql-test-app-0: 01:47:18 ERROR juju.worker.uniter.operation hook "database-relation-changed" (via hook dispatching script: dispatch) failed: exit status 1
unit-mysql-test-app-1: 01:47:21 ERROR unit.mysql-test-app/1.juju-log database:4: Uncaught exception while in charm code:
Traceback (most recent call last):
  File "/var/lib/juju/agents/unit-mysql-test-app-1/charm/venv/lib/python3.10/site-packages/mysql/connector/connection_cext.py", line 611, in cmd_query
    self._cmysql.query(
_mysql_connector.MySQLInterfaceError: Table 'continuous_writes_database.data' doesn't exist

The above exception was the direct cause of the following exception:

Traceback (most recent call last):
  File "/var/lib/juju/agents/unit-mysql-test-app-1/charm/src/charm.py", line 485, in <module>
    main(MySQLTestApplication)
  File "/var/lib/juju/agents/unit-mysql-test-app-1/charm/venv/lib/python3.10/site-packages/ops/main.py", line 40, in main
    return _main.main(charm_class=charm_class, use_juju_for_storage=use_juju_for_storage)
  File "/var/lib/juju/agents/unit-mysql-test-app-1/charm/venv/lib/python3.10/site-packages/ops/_main.py", line 558, in main
    manager.run()
  File "/var/lib/juju/agents/unit-mysql-test-app-1/charm/venv/lib/python3.10/site-packages/ops/_main.py", line 543, in run
    self._emit()
  File "/var/lib/juju/agents/unit-mysql-test-app-1/charm/venv/lib/python3.10/site-packages/ops/_main.py", line 502, in _emit
    self._emit_charm_event(self.dispatcher.event_name)
  File "/var/lib/juju/agents/unit-mysql-test-app-1/charm/venv/lib/python3.10/site-packages/ops/_main.py", line 530, in _emit_charm_event
    event_to_emit.emit(*args, **kwargs)
  File "/var/lib/juju/agents/unit-mysql-test-app-1/charm/venv/lib/python3.10/site-packages/ops/framework.py", line 347, in emit
    framework._emit(event)
  File "/var/lib/juju/agents/unit-mysql-test-app-1/charm/venv/lib/python3.10/site-packages/ops/framework.py", line 906, in _emit
    self._reemit(event_path)
  File "/var/lib/juju/agents/unit-mysql-test-app-1/charm/venv/lib/python3.10/site-packages/ops/framework.py", line 996, in _reemit
    custom_handler(event)
  File "/var/lib/juju/agents/unit-mysql-test-app-1/charm/lib/charms/data_platform_libs/v0/data_interfaces.py", line 3143, in _on_relation_changed_event
    getattr(self.on, "endpoints_changed").emit(
  File "/var/lib/juju/agents/unit-mysql-test-app-1/charm/venv/lib/python3.10/site-packages/ops/framework.py", line 347, in emit
    framework._emit(event)
  File "/var/lib/juju/agents/unit-mysql-test-app-1/charm/venv/lib/python3.10/site-packages/ops/framework.py", line 906, in _emit
    self._reemit(event_path)
  File "/var/lib/juju/agents/unit-mysql-test-app-1/charm/venv/lib/python3.10/site-packages/ops/framework.py", line 996, in _reemit
    custom_handler(event)
  File "/var/lib/juju/agents/unit-mysql-test-app-1/charm/src/charm.py", line 358, in _on_endpoints_changed
    count = self._max_written_value()
  File "/var/lib/juju/agents/unit-mysql-test-app-1/charm/src/charm.py", line 241, in _max_written_value
    cursor.execute(
  File "/var/lib/juju/agents/unit-mysql-test-app-1/charm/venv/lib/python3.10/site-packages/mysql/connector/cursor_cext.py", line 330, in execute
    result = self._cnx.cmd_query(
  File "/var/lib/juju/agents/unit-mysql-test-app-1/charm/venv/lib/python3.10/site-packages/mysql/connector/connection_cext.py", line 619, in cmd_query
    raise get_mysql_exception(
mysql.connector.errors.ProgrammingError: 1146 (42S02): Table 'continuous_writes_database.data' doesn't exist
unit-mysql-test-app-1: 01:47:22 ERROR juju.worker.uniter.operation hook "database-relation-changed" (via hook dispatching script: dispatch) failed: exit status 1
unit-mysql-test-app-0: 01:49:57 ERROR unit.mysql-test-app/0.juju-log database:4: Uncaught exception while in charm code:
Traceback (most recent call last):
  File "/var/lib/juju/agents/unit-mysql-test-app-0/charm/venv/lib/python3.10/site-packages/mysql/connector/connection_cext.py", line 611, in cmd_query
    self._cmysql.query(
_mysql_connector.MySQLInterfaceError: Table 'continuous_writes_database.data' doesn't exist

The above exception was the direct cause of the following exception:

Traceback (most recent call last):
  File "/var/lib/juju/agents/unit-mysql-test-app-0/charm/src/charm.py", line 485, in <module>
    main(MySQLTestApplication)
  File "/var/lib/juju/agents/unit-mysql-test-app-0/charm/venv/lib/python3.10/site-packages/ops/main.py", line 40, in main
    return _main.main(charm_class=charm_class, use_juju_for_storage=use_juju_for_storage)
  File "/var/lib/juju/agents/unit-mysql-test-app-0/charm/venv/lib/python3.10/site-packages/ops/_main.py", line 558, in main
    manager.run()
  File "/var/lib/juju/agents/unit-mysql-test-app-0/charm/venv/lib/python3.10/site-packages/ops/_main.py", line 543, in run
    self._emit()
  File "/var/lib/juju/agents/unit-mysql-test-app-0/charm/venv/lib/python3.10/site-packages/ops/_main.py", line 502, in _emit
    self._emit_charm_event(self.dispatcher.event_name)
  File "/var/lib/juju/agents/unit-mysql-test-app-0/charm/venv/lib/python3.10/site-packages/ops/_main.py", line 530, in _emit_charm_event
    event_to_emit.emit(*args, **kwargs)
  File "/var/lib/juju/agents/unit-mysql-test-app-0/charm/venv/lib/python3.10/site-packages/ops/framework.py", line 347, in emit
    framework._emit(event)
  File "/var/lib/juju/agents/unit-mysql-test-app-0/charm/venv/lib/python3.10/site-packages/ops/framework.py", line 906, in _emit
    self._reemit(event_path)
  File "/var/lib/juju/agents/unit-mysql-test-app-0/charm/venv/lib/python3.10/site-packages/ops/framework.py", line 996, in _reemit
    custom_handler(event)
  File "/var/lib/juju/agents/unit-mysql-test-app-0/charm/lib/charms/data_platform_libs/v0/data_interfaces.py", line 3143, in _on_relation_changed_event
    getattr(self.on, "endpoints_changed").emit(
  File "/var/lib/juju/agents/unit-mysql-test-app-0/charm/venv/lib/python3.10/site-packages/ops/framework.py", line 347, in emit
    framework._emit(event)
  File "/var/lib/juju/agents/unit-mysql-test-app-0/charm/venv/lib/python3.10/site-packages/ops/framework.py", line 906, in _emit
    self._reemit(event_path)
  File "/var/lib/juju/agents/unit-mysql-test-app-0/charm/venv/lib/python3.10/site-packages/ops/framework.py", line 996, in _reemit
    custom_handler(event)
  File "/var/lib/juju/agents/unit-mysql-test-app-0/charm/src/charm.py", line 358, in _on_endpoints_changed
    count = self._max_written_value()
  File "/var/lib/juju/agents/unit-mysql-test-app-0/charm/src/charm.py", line 241, in _max_written_value
    cursor.execute(
  File "/var/lib/juju/agents/unit-mysql-test-app-0/charm/venv/lib/python3.10/site-packages/mysql/connector/cursor_cext.py", line 330, in execute
    result = self._cnx.cmd_query(
  File "/var/lib/juju/agents/unit-mysql-test-app-0/charm/venv/lib/python3.10/site-packages/mysql/connector/connection_cext.py", line 619, in cmd_query
    raise get_mysql_exception(
mysql.connector.errors.ProgrammingError: 1146 (42S02): Table 'continuous_writes_database.data' doesn't exist
unit-mysql-test-app-0: 01:49:57 ERROR juju.worker.uniter.operation hook "database-relation-changed" (via hook dispatching script: dispatch) failed: exit status 1
unit-mysql-test-app-1: 01:50:01 ERROR unit.mysql-test-app/1.juju-log database:4: Uncaught exception while in charm code:
Traceback (most recent call last):
  File "/var/lib/juju/agents/unit-mysql-test-app-1/charm/venv/lib/python3.10/site-packages/mysql/connector/connection_cext.py", line 611, in cmd_query
    self._cmysql.query(
_mysql_connector.MySQLInterfaceError: Table 'continuous_writes_database.data' doesn't exist

The above exception was the direct cause of the following exception:

Traceback (most recent call last):
  File "/var/lib/juju/agents/unit-mysql-test-app-1/charm/src/charm.py", line 485, in <module>
    main(MySQLTestApplication)
  File "/var/lib/juju/agents/unit-mysql-test-app-1/charm/venv/lib/python3.10/site-packages/ops/main.py", line 40, in main
    return _main.main(charm_class=charm_class, use_juju_for_storage=use_juju_for_storage)
  File "/var/lib/juju/agents/unit-mysql-test-app-1/charm/venv/lib/python3.10/site-packages/ops/_main.py", line 558, in main
    manager.run()
  File "/var/lib/juju/agents/unit-mysql-test-app-1/charm/venv/lib/python3.10/site-packages/ops/_main.py", line 543, in run
    self._emit()
  File "/var/lib/juju/agents/unit-mysql-test-app-1/charm/venv/lib/python3.10/site-packages/ops/_main.py", line 502, in _emit
    self._emit_charm_event(self.dispatcher.event_name)
  File "/var/lib/juju/agents/unit-mysql-test-app-1/charm/venv/lib/python3.10/site-packages/ops/_main.py", line 530, in _emit_charm_event
    event_to_emit.emit(*args, **kwargs)
  File "/var/lib/juju/agents/unit-mysql-test-app-1/charm/venv/lib/python3.10/site-packages/ops/framework.py", line 347, in emit
    framework._emit(event)
  File "/var/lib/juju/agents/unit-mysql-test-app-1/charm/venv/lib/python3.10/site-packages/ops/framework.py", line 906, in _emit
    self._reemit(event_path)
  File "/var/lib/juju/agents/unit-mysql-test-app-1/charm/venv/lib/python3.10/site-packages/ops/framework.py", line 996, in _reemit
    custom_handler(event)
  File "/var/lib/juju/agents/unit-mysql-test-app-1/charm/lib/charms/data_platform_libs/v0/data_interfaces.py", line 3143, in _on_relation_changed_event
    getattr(self.on, "endpoints_changed").emit(
  File "/var/lib/juju/agents/unit-mysql-test-app-1/charm/venv/lib/python3.10/site-packages/ops/framework.py", line 347, in emit
    framework._emit(event)
  File "/var/lib/juju/agents/unit-mysql-test-app-1/charm/venv/lib/python3.10/site-packages/ops/framework.py", line 906, in _emit
    self._reemit(event_path)
  File "/var/lib/juju/agents/unit-mysql-test-app-1/charm/venv/lib/python3.10/site-packages/ops/framework.py", line 996, in _reemit
    custom_handler(event)
  File "/var/lib/juju/agents/unit-mysql-test-app-1/charm/src/charm.py", line 358, in _on_endpoints_changed
    count = self._max_written_value()
  File "/var/lib/juju/agents/unit-mysql-test-app-1/charm/src/charm.py", line 241, in _max_written_value
    cursor.execute(
  File "/var/lib/juju/agents/unit-mysql-test-app-1/charm/venv/lib/python3.10/site-packages/mysql/connector/cursor_cext.py", line 330, in execute
    result = self._cnx.cmd_query(
  File "/var/lib/juju/agents/unit-mysql-test-app-1/charm/venv/lib/python3.10/site-packages/mysql/connector/connection_cext.py", line 619, in cmd_query
    raise get_mysql_exception(
mysql.connector.errors.ProgrammingError: 1146 (42S02): Table 'continuous_writes_database.data' doesn't exist
unit-mysql-test-app-1: 01:50:01 ERROR juju.worker.uniter.operation hook "database-relation-changed" (via hook dispatching script: dispatch) failed: exit status 1

[32mINFO    [0m pytest_operator.plugin:plugin.py:947 Forgetting model main...