[32mINFO    [0m integration.high_availability.conftest:conftest.py:23 Clearing continuous writes
[32mINFO    [0m integration.high_availability.conftest:conftest.py:26 Starting continuous writes
[32mINFO    [0m integration.helpers:helpers.py:475 Retrieving primary unit
[32mINFO    [0m integration.high_availability.high_availability_helpers:high_availability_helpers.py:361 Ensure continuous writes are incrementing
[32mINFO    [0m integration.helpers:helpers.py:475 Retrieving primary unit
[32mINFO    [0m integration.high_availability.test_self_healing:test_self_healing.py:393 Stopping server on unit mysql/2
[32mINFO    [0m integration.high_availability.test_self_healing:test_self_healing.py:396 Removing data directory
[32mINFO    [0m integration.high_availability.test_self_healing:test_self_healing.py:412 Purge binlogs on unit mysql/0
[32mINFO    [0m integration.high_availability.test_self_healing:test_self_healing.py:412 Purge binlogs on unit mysql/1
[32mINFO    [0m integration.high_availability.test_self_healing:test_self_healing.py:420 Waiting unit to enter in maintenance.
[32mINFO    [0m integration.high_availability.test_self_healing:test_self_healing.py:427 Waiting unit to be back online.
[32mINFO    [0m integration.helpers:helpers.py:475 Retrieving primary unit
[32mINFO    [0m integration.high_availability.test_self_healing:test_self_healing.py:439 Check if instance in cluster
[32mINFO    [0m integration.high_availability.high_availability_helpers:high_availability_helpers.py:361 Ensure continuous writes are incrementing
[32mINFO    [0m integration.helpers:helpers.py:475 Retrieving primary unit
[32mINFO    [0m integration.helpers:helpers.py:475 Retrieving primary unit
[32mINFO    [0m integration.helpers:helpers.py:475 Retrieving primary unit
[32mINFO    [0m integration.high_availability.conftest:conftest.py:31 Clearing continuous writes
[32mINFO    [0m pytest_operator.plugin:plugin.py:790 Model status:

Model  Controller           Cloud/Region         Version  SLA          Timestamp
test   localhost-localhost  localhost/localhost  3.1.7    unsupported  01:50:53Z

App             Version          Status  Scale  Charm           Channel      Rev  Exposed  Message
mysql           8.0.36-0ubun...  active      3  mysql                          0  no       
mysql-test-app  0.0.2            active      1  mysql-test-app  latest/edge   37  no       

Unit               Workload  Agent  Machine  Public address  Ports           Message
mysql-test-app/0*  active    idle   3        10.183.110.239                  
mysql/0            active    idle   0        10.183.110.208  3306,33060/tcp  
mysql/1            active    idle   1        10.183.110.176  3306,33060/tcp  Primary
mysql/2*           active    idle   2        10.183.110.21   3306,33060/tcp  

Machine  State    Address         Inst id        Base          AZ  Message
0        started  10.183.110.208  juju-e74aaf-0  ubuntu@22.04      Running
1        started  10.183.110.176  juju-e74aaf-1  ubuntu@22.04      Running
2        started  10.183.110.21   juju-e74aaf-2  ubuntu@22.04      Running
3        started  10.183.110.239  juju-e74aaf-3  ubuntu@22.04      Running

[32mINFO    [0m pytest_operator.plugin:plugin.py:796 Juju error logs:

machine-2: 01:33:02 ERROR juju.worker.dependency "lxd-container-provisioner" manifold worker returned unexpected error: container types not yet available
machine-2: 01:33:02 ERROR juju.worker.dependency "kvm-container-provisioner" manifold worker returned unexpected error: container types not yet available
machine-2: 01:33:02 ERROR juju.worker.dependency "broker-tracker" manifold worker returned unexpected error: no container types determined
unit-mysql-2: 01:33:02 ERROR juju.worker.meterstatus error running "meter-status-changed": charm missing from disk
machine-0: 01:33:03 ERROR juju.worker.dependency "lxd-container-provisioner" manifold worker returned unexpected error: container types not yet available
machine-0: 01:33:03 ERROR juju.worker.dependency "kvm-container-provisioner" manifold worker returned unexpected error: container types not yet available
machine-0: 01:33:03 ERROR juju.worker.dependency "broker-tracker" manifold worker returned unexpected error: no container types determined
unit-mysql-0: 01:33:03 ERROR juju.worker.meterstatus error running "meter-status-changed": charm missing from disk
machine-1: 01:33:07 ERROR juju.worker.dependency "lxd-container-provisioner" manifold worker returned unexpected error: container types not yet available
machine-1: 01:33:07 ERROR juju.worker.dependency "kvm-container-provisioner" manifold worker returned unexpected error: container types not yet available
machine-1: 01:33:07 ERROR juju.worker.dependency "broker-tracker" manifold worker returned unexpected error: no container types determined
unit-mysql-1: 01:33:07 ERROR juju.worker.meterstatus error running "meter-status-changed": charm missing from disk
machine-3: 01:36:33 ERROR juju.worker.dependency "kvm-container-provisioner" manifold worker returned unexpected error: container types not yet available
machine-3: 01:36:33 ERROR juju.worker.dependency "broker-tracker" manifold worker returned unexpected error: no container types determined
machine-3: 01:36:33 ERROR juju.worker.dependency "lxd-container-provisioner" manifold worker returned unexpected error: container types not yet available
unit-mysql-test-app-0: 01:36:33 ERROR juju.worker.meterstatus error running "meter-status-changed": charm missing from disk
unit-mysql-0: 01:37:50 ERROR unit.mysql/0.juju-log Failed to get cluster status for test_cluster
unit-mysql-0: 01:37:57 ERROR unit.mysql/0.juju-log Failed to get cluster status for test_cluster
unit-mysql-2: 01:37:59 ERROR unit.mysql/2.juju-log Failed to get cluster status for test_cluster
unit-mysql-2: 01:37:59 ERROR unit.mysql/2.juju-log Failed to get cluster members
Traceback (most recent call last):
  File "/var/lib/juju/agents/unit-mysql-2/charm/src/relations/mysql_provider.py", line 163, in _update_endpoints
    rw_endpoints, ro_endpoints, _ = self.charm._mysql.get_cluster_endpoints()
  File "/var/lib/juju/agents/unit-mysql-2/charm/lib/charms/mysql/v0/mysql.py", line 1900, in get_cluster_endpoints
    raise MySQLGetClusterEndpointsError("Failed to get endpoints from cluster status")
charms.mysql.v0.mysql.MySQLGetClusterEndpointsError: Failed to get endpoints from cluster status
unit-mysql-0: 01:38:05 ERROR unit.mysql/0.juju-log Failed to get cluster status for test_cluster
unit-mysql-2: 01:38:09 ERROR unit.mysql/2.juju-log Failed to get cluster status for test_cluster
unit-mysql-2: 01:38:09 ERROR unit.mysql/2.juju-log Failed to get cluster members
Traceback (most recent call last):
  File "/var/lib/juju/agents/unit-mysql-2/charm/src/relations/mysql_provider.py", line 163, in _update_endpoints
    rw_endpoints, ro_endpoints, _ = self.charm._mysql.get_cluster_endpoints()
  File "/var/lib/juju/agents/unit-mysql-2/charm/lib/charms/mysql/v0/mysql.py", line 1900, in get_cluster_endpoints
    raise MySQLGetClusterEndpointsError("Failed to get endpoints from cluster status")
charms.mysql.v0.mysql.MySQLGetClusterEndpointsError: Failed to get endpoints from cluster status
unit-mysql-2: 01:38:19 ERROR unit.mysql/2.juju-log Failed to get cluster status for test_cluster
unit-mysql-2: 01:38:19 ERROR unit.mysql/2.juju-log Failed to get cluster members
Traceback (most recent call last):
  File "/var/lib/juju/agents/unit-mysql-2/charm/src/relations/mysql_provider.py", line 163, in _update_endpoints
    rw_endpoints, ro_endpoints, _ = self.charm._mysql.get_cluster_endpoints()
  File "/var/lib/juju/agents/unit-mysql-2/charm/lib/charms/mysql/v0/mysql.py", line 1900, in get_cluster_endpoints
    raise MySQLGetClusterEndpointsError("Failed to get endpoints from cluster status")
charms.mysql.v0.mysql.MySQLGetClusterEndpointsError: Failed to get endpoints from cluster status
machine-1: 01:41:37 ERROR juju.worker.dependency "api-caller" manifold worker returned unexpected error: api connection broken unexpectedly
unit-mysql-0: 01:44:02 ERROR unit.mysql/0.juju-log Failed to flush ERROR LOGS logs.
Traceback (most recent call last):
  File "/var/lib/juju/agents/unit-mysql-0/charm/src/mysql_vm_helpers.py", line 678, in _run_mysqlsh_script
    return subprocess.check_output(
  File "/usr/lib/python3.10/subprocess.py", line 421, in check_output
    return run(*popenargs, stdout=PIPE, timeout=timeout, check=True,
  File "/usr/lib/python3.10/subprocess.py", line 526, in run
    raise CalledProcessError(retcode, process.args,
subprocess.CalledProcessError: Command '['charmed-mysql.mysqlsh', '--no-wizard', '--python', '-f', '/var/snap/charmed-mysql/common/tmp4wks1leh']' returned non-zero exit status 1.

During handling of the above exception, another exception occurred:

Traceback (most recent call last):
  File "/var/lib/juju/agents/unit-mysql-0/charm/lib/charms/mysql/v0/mysql.py", line 3089, in flush_mysql_logs
    self._run_mysqlsh_script("\n".join(flush_logs_commands), timeout=50)
  File "/var/lib/juju/agents/unit-mysql-0/charm/src/mysql_vm_helpers.py", line 682, in _run_mysqlsh_script
    raise MySQLClientError(e.stderr)
charms.mysql.v0.mysql.MySQLClientError: b'Traceback (most recent call last):\n  File "<string>", line 1, in <module>\nmysqlsh.DBError: MySQL Error (2003): Shell.connect: Can\'t connect to MySQL server on \'juju-e74aaf-0.lxd:3306\' (111)\n'
unit-mysql-0: 01:44:03 ERROR unit.mysql/0.juju-log Failed to flush GENERAL LOGS logs.
Traceback (most recent call last):
  File "/var/lib/juju/agents/unit-mysql-0/charm/src/mysql_vm_helpers.py", line 678, in _run_mysqlsh_script
    return subprocess.check_output(
  File "/usr/lib/python3.10/subprocess.py", line 421, in check_output
    return run(*popenargs, stdout=PIPE, timeout=timeout, check=True,
  File "/usr/lib/python3.10/subprocess.py", line 526, in run
    raise CalledProcessError(retcode, process.args,
subprocess.CalledProcessError: Command '['charmed-mysql.mysqlsh', '--no-wizard', '--python', '-f', '/var/snap/charmed-mysql/common/tmp4d8sc_tp']' returned non-zero exit status 1.

During handling of the above exception, another exception occurred:

Traceback (most recent call last):
  File "/var/lib/juju/agents/unit-mysql-0/charm/lib/charms/mysql/v0/mysql.py", line 3089, in flush_mysql_logs
    self._run_mysqlsh_script("\n".join(flush_logs_commands), timeout=50)
  File "/var/lib/juju/agents/unit-mysql-0/charm/src/mysql_vm_helpers.py", line 682, in _run_mysqlsh_script
    raise MySQLClientError(e.stderr)
charms.mysql.v0.mysql.MySQLClientError: b'Traceback (most recent call last):\n  File "<string>", line 1, in <module>\nmysqlsh.DBError: MySQL Error (2003): Shell.connect: Can\'t connect to MySQL server on \'juju-e74aaf-0.lxd:3306\' (111)\n'
unit-mysql-2: 01:45:05 ERROR unit.mysql/2.juju-log Failed to flush GENERAL LOGS logs.
Traceback (most recent call last):
  File "/var/lib/juju/agents/unit-mysql-2/charm/src/mysql_vm_helpers.py", line 678, in _run_mysqlsh_script
    return subprocess.check_output(
  File "/usr/lib/python3.10/subprocess.py", line 421, in check_output
    return run(*popenargs, stdout=PIPE, timeout=timeout, check=True,
  File "/usr/lib/python3.10/subprocess.py", line 526, in run
    raise CalledProcessError(retcode, process.args,
subprocess.CalledProcessError: Command '['charmed-mysql.mysqlsh', '--no-wizard', '--python', '-f', '/var/snap/charmed-mysql/common/tmpdjtktr0g']' returned non-zero exit status 1.

During handling of the above exception, another exception occurred:

Traceback (most recent call last):
  File "/var/lib/juju/agents/unit-mysql-2/charm/lib/charms/mysql/v0/mysql.py", line 3089, in flush_mysql_logs
    self._run_mysqlsh_script("\n".join(flush_logs_commands), timeout=50)
  File "/var/lib/juju/agents/unit-mysql-2/charm/src/mysql_vm_helpers.py", line 682, in _run_mysqlsh_script
    raise MySQLClientError(e.stderr)
charms.mysql.v0.mysql.MySQLClientError: b'Traceback (most recent call last):\n  File "<string>", line 1, in <module>\nmysqlsh.DBError: MySQL Error (1045): Shell.connect: Access denied for user \'serverconfig\'@\'juju-e74aaf-2\' (using password: YES)\n'
unit-mysql-0: 01:45:09 ERROR unit.mysql/0.juju-log Failed to flush GENERAL LOGS logs.
Traceback (most recent call last):
  File "/var/lib/juju/agents/unit-mysql-0/charm/src/mysql_vm_helpers.py", line 678, in _run_mysqlsh_script
    return subprocess.check_output(
  File "/usr/lib/python3.10/subprocess.py", line 421, in check_output
    return run(*popenargs, stdout=PIPE, timeout=timeout, check=True,
  File "/usr/lib/python3.10/subprocess.py", line 526, in run
    raise CalledProcessError(retcode, process.args,
subprocess.CalledProcessError: Command '['charmed-mysql.mysqlsh', '--no-wizard', '--python', '-f', '/var/snap/charmed-mysql/common/tmp85ltsx31']' returned non-zero exit status 1.

During handling of the above exception, another exception occurred:

Traceback (most recent call last):
  File "/var/lib/juju/agents/unit-mysql-0/charm/lib/charms/mysql/v0/mysql.py", line 3089, in flush_mysql_logs
    self._run_mysqlsh_script("\n".join(flush_logs_commands), timeout=50)
  File "/var/lib/juju/agents/unit-mysql-0/charm/src/mysql_vm_helpers.py", line 682, in _run_mysqlsh_script
    raise MySQLClientError(e.stderr)
charms.mysql.v0.mysql.MySQLClientError: b'Traceback (most recent call last):\n  File "<string>", line 1, in <module>\nmysqlsh.DBError: MySQL Error (2013): Shell.connect: Lost connection to MySQL server at \'reading initial communication packet\', system error: 104\n'
unit-mysql-0: 01:46:02 ERROR unit.mysql/0.juju-log Failed to flush ERROR LOGS logs.
Traceback (most recent call last):
  File "/var/lib/juju/agents/unit-mysql-0/charm/src/mysql_vm_helpers.py", line 678, in _run_mysqlsh_script
    return subprocess.check_output(
  File "/usr/lib/python3.10/subprocess.py", line 421, in check_output
    return run(*popenargs, stdout=PIPE, timeout=timeout, check=True,
  File "/usr/lib/python3.10/subprocess.py", line 526, in run
    raise CalledProcessError(retcode, process.args,
subprocess.CalledProcessError: Command '['charmed-mysql.mysqlsh', '--no-wizard', '--python', '-f', '/var/snap/charmed-mysql/common/tmpv6o939dw']' returned non-zero exit status 1.

During handling of the above exception, another exception occurred:

Traceback (most recent call last):
  File "/var/lib/juju/agents/unit-mysql-0/charm/lib/charms/mysql/v0/mysql.py", line 3089, in flush_mysql_logs
    self._run_mysqlsh_script("\n".join(flush_logs_commands), timeout=50)
  File "/var/lib/juju/agents/unit-mysql-0/charm/src/mysql_vm_helpers.py", line 682, in _run_mysqlsh_script
    raise MySQLClientError(e.stderr)
charms.mysql.v0.mysql.MySQLClientError: b'Traceback (most recent call last):\n  File "<string>", line 1, in <module>\nmysqlsh.DBError: MySQL Error (2003): Shell.connect: Can\'t connect to MySQL server on \'juju-e74aaf-0.lxd:3306\' (111)\n'
unit-mysql-2: 01:46:02 ERROR unit.mysql/2.juju-log Failed to flush ERROR LOGS logs.
Traceback (most recent call last):
  File "/var/lib/juju/agents/unit-mysql-2/charm/src/mysql_vm_helpers.py", line 678, in _run_mysqlsh_script
    return subprocess.check_output(
  File "/usr/lib/python3.10/subprocess.py", line 421, in check_output
    return run(*popenargs, stdout=PIPE, timeout=timeout, check=True,
  File "/usr/lib/python3.10/subprocess.py", line 526, in run
    raise CalledProcessError(retcode, process.args,
subprocess.CalledProcessError: Command '['charmed-mysql.mysqlsh', '--no-wizard', '--python', '-f', '/var/snap/charmed-mysql/common/tmppdp7bss_']' returned non-zero exit status 1.

During handling of the above exception, another exception occurred:

Traceback (most recent call last):
  File "/var/lib/juju/agents/unit-mysql-2/charm/lib/charms/mysql/v0/mysql.py", line 3089, in flush_mysql_logs
    self._run_mysqlsh_script("\n".join(flush_logs_commands), timeout=50)
  File "/var/lib/juju/agents/unit-mysql-2/charm/src/mysql_vm_helpers.py", line 682, in _run_mysqlsh_script
    raise MySQLClientError(e.stderr)
charms.mysql.v0.mysql.MySQLClientError: b'Traceback (most recent call last):\n  File "<string>", line 1, in <module>\nmysqlsh.DBError: MySQL Error (2003): Shell.connect: Can\'t connect to MySQL server on \'juju-e74aaf-2.lxd:3306\' (111)\n'
unit-mysql-2: 01:46:39 ERROR unit.mysql/2.juju-log Failed to get cluster status for test_cluster
unit-mysql-2: 01:46:39 ERROR unit.mysql/2.juju-log Failed to get cluster members
Traceback (most recent call last):
  File "/var/lib/juju/agents/unit-mysql-2/charm/src/relations/mysql_provider.py", line 163, in _update_endpoints
    rw_endpoints, ro_endpoints, _ = self.charm._mysql.get_cluster_endpoints()
  File "/var/lib/juju/agents/unit-mysql-2/charm/lib/charms/mysql/v0/mysql.py", line 1900, in get_cluster_endpoints
    raise MySQLGetClusterEndpointsError("Failed to get endpoints from cluster status")
charms.mysql.v0.mysql.MySQLGetClusterEndpointsError: Failed to get endpoints from cluster status
unit-mysql-2: 01:49:03 ERROR unit.mysql/2.juju-log Failed to flush ERROR LOGS logs.
Traceback (most recent call last):
  File "/var/lib/juju/agents/unit-mysql-2/charm/src/mysql_vm_helpers.py", line 678, in _run_mysqlsh_script
    return subprocess.check_output(
  File "/usr/lib/python3.10/subprocess.py", line 421, in check_output
    return run(*popenargs, stdout=PIPE, timeout=timeout, check=True,
  File "/usr/lib/python3.10/subprocess.py", line 526, in run
    raise CalledProcessError(retcode, process.args,
subprocess.CalledProcessError: Command '['charmed-mysql.mysqlsh', '--no-wizard', '--python', '-f', '/var/snap/charmed-mysql/common/tmp3vygn5wb']' returned non-zero exit status 1.

During handling of the above exception, another exception occurred:

Traceback (most recent call last):
  File "/var/lib/juju/agents/unit-mysql-2/charm/lib/charms/mysql/v0/mysql.py", line 3089, in flush_mysql_logs
    self._run_mysqlsh_script("\n".join(flush_logs_commands), timeout=50)
  File "/var/lib/juju/agents/unit-mysql-2/charm/src/mysql_vm_helpers.py", line 682, in _run_mysqlsh_script
    raise MySQLClientError(e.stderr)
charms.mysql.v0.mysql.MySQLClientError: b'Traceback (most recent call last):\n  File "<string>", line 1, in <module>\nmysqlsh.DBError: MySQL Error (2003): Shell.connect: Can\'t connect to MySQL server on \'juju-e74aaf-2.lxd:3306\' (111)\n'
unit-mysql-2: 01:49:04 ERROR unit.mysql/2.juju-log Failed to flush GENERAL LOGS logs.
Traceback (most recent call last):
  File "/var/lib/juju/agents/unit-mysql-2/charm/src/mysql_vm_helpers.py", line 678, in _run_mysqlsh_script
    return subprocess.check_output(
  File "/usr/lib/python3.10/subprocess.py", line 421, in check_output
    return run(*popenargs, stdout=PIPE, timeout=timeout, check=True,
  File "/usr/lib/python3.10/subprocess.py", line 526, in run
    raise CalledProcessError(retcode, process.args,
subprocess.CalledProcessError: Command '['charmed-mysql.mysqlsh', '--no-wizard', '--python', '-f', '/var/snap/charmed-mysql/common/tmp5shitygq']' returned non-zero exit status 1.

During handling of the above exception, another exception occurred:

Traceback (most recent call last):
  File "/var/lib/juju/agents/unit-mysql-2/charm/lib/charms/mysql/v0/mysql.py", line 3089, in flush_mysql_logs
    self._run_mysqlsh_script("\n".join(flush_logs_commands), timeout=50)
  File "/var/lib/juju/agents/unit-mysql-2/charm/src/mysql_vm_helpers.py", line 682, in _run_mysqlsh_script
    raise MySQLClientError(e.stderr)
charms.mysql.v0.mysql.MySQLClientError: b'Traceback (most recent call last):\n  File "<string>", line 1, in <module>\nmysqlsh.DBError: MySQL Error (2003): Shell.connect: Can\'t connect to MySQL server on \'juju-e74aaf-2.lxd:3306\' (111)\n'
unit-mysql-2: 01:49:48 ERROR unit.mysql/2.juju-log Failed to get member state: mysqld daemon is down
unit-mysql-2: 01:49:58 ERROR unit.mysql/2.juju-log Failed to get member state: mysqld daemon is down
unit-mysql-2: 01:50:08 ERROR unit.mysql/2.juju-log Failed to get member state: mysqld daemon is down
unit-mysql-2: 01:50:10 ERROR unit.mysql/2.juju-log Failed to get cluster status for test_cluster
unit-mysql-2: 01:50:10 ERROR unit.mysql/2.juju-log Failed to get cluster members
Traceback (most recent call last):
  File "/var/lib/juju/agents/unit-mysql-2/charm/src/relations/mysql_provider.py", line 163, in _update_endpoints
    rw_endpoints, ro_endpoints, _ = self.charm._mysql.get_cluster_endpoints()
  File "/var/lib/juju/agents/unit-mysql-2/charm/lib/charms/mysql/v0/mysql.py", line 1900, in get_cluster_endpoints
    raise MySQLGetClusterEndpointsError("Failed to get endpoints from cluster status")
charms.mysql.v0.mysql.MySQLGetClusterEndpointsError: Failed to get endpoints from cluster status

[32mINFO    [0m pytest_operator.plugin:plugin.py:862 Forgetting main...