[32mINFO    [0m integration.high_availability.conftest:conftest.py:23 Clearing continuous writes
[32mINFO    [0m integration.high_availability.conftest:conftest.py:26 Starting continuous writes
[32mINFO    [0m integration.helpers:helpers.py:481 Retrieving primary unit
[32mINFO    [0m integration.high_availability.high_availability_helpers:high_availability_helpers.py:356 Ensure continuous writes are incrementing
[32mINFO    [0m integration.helpers:helpers.py:481 Retrieving primary unit
[32mINFO    [0m integration.high_availability.test_self_healing:test_self_healing.py:391 Stopping server on unit mysql/0
[32mINFO    [0m integration.high_availability.test_self_healing:test_self_healing.py:394 Removing data directory
[32mINFO    [0m integration.high_availability.test_self_healing:test_self_healing.py:410 Purge binlogs on unit mysql/1
[32mINFO    [0m integration.high_availability.test_self_healing:test_self_healing.py:410 Purge binlogs on unit mysql/2
[32mINFO    [0m integration.high_availability.test_self_healing:test_self_healing.py:418 Waiting unit to enter in maintenance.
[32mINFO    [0m integration.high_availability.test_self_healing:test_self_healing.py:425 Waiting unit to be back online.
[32mINFO    [0m integration.helpers:helpers.py:481 Retrieving primary unit
[32mINFO    [0m integration.high_availability.test_self_healing:test_self_healing.py:437 Check if instance in cluster
[32mINFO    [0m integration.high_availability.high_availability_helpers:high_availability_helpers.py:356 Ensure continuous writes are incrementing
[32mINFO    [0m integration.helpers:helpers.py:481 Retrieving primary unit
[32mINFO    [0m integration.helpers:helpers.py:481 Retrieving primary unit
[32mINFO    [0m integration.helpers:helpers.py:481 Retrieving primary unit
[32mINFO    [0m integration.high_availability.conftest:conftest.py:31 Clearing continuous writes
[32mINFO    [0m pytest_operator.plugin:plugin.py:790 Model status:

Model  Controller           Cloud/Region         Version  SLA          Timestamp
test   localhost-localhost  localhost/localhost  3.4.3    unsupported  01:55:05Z

App             Version          Status  Scale  Charm           Channel      Rev  Exposed  Message
mysql           8.0.37-0ubun...  active      3  mysql                          0  no       
mysql-test-app  0.0.2            active      1  mysql-test-app  latest/edge   46  no       

Unit               Workload  Agent      Machine  Public address  Ports           Message
mysql-test-app/0*  active    idle       3        10.24.109.245                   
mysql/0*           active    executing  0        10.24.109.69    3306,33060/tcp  
mysql/1            active    executing  1        10.24.109.174   3306,33060/tcp  Primary
mysql/2            active    idle       2        10.24.109.45    3306,33060/tcp  

Machine  State    Address        Inst id        Base          AZ  Message
0        started  10.24.109.69   juju-8c0344-0  ubuntu@22.04      Running
1        started  10.24.109.174  juju-8c0344-1  ubuntu@22.04      Running
2        started  10.24.109.45   juju-8c0344-2  ubuntu@22.04      Running
3        started  10.24.109.245  juju-8c0344-3  ubuntu@22.04      Running

[32mINFO    [0m pytest_operator.plugin:plugin.py:796 Juju error logs:

machine-1: 01:36:29 ERROR juju.worker.dependency "kvm-container-provisioner" manifold worker returned unexpected error: container types not yet available
machine-1: 01:36:29 ERROR juju.worker.dependency "broker-tracker" manifold worker returned unexpected error: no container types determined
machine-1: 01:36:29 ERROR juju.worker.dependency "lxd-container-provisioner" manifold worker returned unexpected error: container types not yet available
unit-mysql-1: 01:36:29 ERROR juju.worker.meterstatus error running "meter-status-changed": charm missing from disk
machine-0: 01:36:34 ERROR juju.worker.dependency "broker-tracker" manifold worker returned unexpected error: no container types determined
machine-0: 01:36:34 ERROR juju.worker.dependency "lxd-container-provisioner" manifold worker returned unexpected error: container types not yet available
machine-0: 01:36:34 ERROR juju.worker.dependency "kvm-container-provisioner" manifold worker returned unexpected error: container types not yet available
unit-mysql-0: 01:36:34 ERROR juju.worker.meterstatus error running "meter-status-changed": charm missing from disk
machine-2: 01:36:36 ERROR juju.worker.dependency "broker-tracker" manifold worker returned unexpected error: no container types determined
machine-2: 01:36:36 ERROR juju.worker.dependency "kvm-container-provisioner" manifold worker returned unexpected error: container types not yet available
machine-2: 01:36:36 ERROR juju.worker.dependency "lxd-container-provisioner" manifold worker returned unexpected error: container types not yet available
unit-mysql-2: 01:36:36 ERROR juju.worker.meterstatus error running "meter-status-changed": charm missing from disk
machine-3: 01:39:25 ERROR juju.worker.dependency "kvm-container-provisioner" manifold worker returned unexpected error: container types not yet available
machine-3: 01:39:25 ERROR juju.worker.dependency "lxd-container-provisioner" manifold worker returned unexpected error: container types not yet available
machine-3: 01:39:25 ERROR juju.worker.dependency "broker-tracker" manifold worker returned unexpected error: no container types determined
unit-mysql-test-app-0: 01:39:25 ERROR juju.worker.meterstatus error running "meter-status-changed": charm missing from disk
unit-mysql-0: 01:40:47 ERROR unit.mysql/0.juju-log Failed to get cluster status for test_cluster
unit-mysql-0: 01:40:56 ERROR unit.mysql/0.juju-log Failed to get cluster status for test_cluster
unit-mysql-1: 01:40:57 ERROR unit.mysql/1.juju-log Failed to get cluster status for test_cluster
unit-mysql-1: 01:40:57 ERROR unit.mysql/1.juju-log Failed to get cluster members
Traceback (most recent call last):
  File "/var/lib/juju/agents/unit-mysql-1/charm/src/relations/mysql_provider.py", line 163, in _update_endpoints
    rw_endpoints, ro_endpoints, _ = self.charm._mysql.get_cluster_endpoints()
  File "/var/lib/juju/agents/unit-mysql-1/charm/lib/charms/tempo_k8s/v1/charm_tracing.py", line 647, in wrapped_function
    return callable(*args, **kwargs)  # type: ignore
  File "/var/lib/juju/agents/unit-mysql-1/charm/lib/charms/mysql/v0/mysql.py", line 1945, in get_cluster_endpoints
    raise MySQLGetClusterEndpointsError("Failed to get endpoints from cluster status")
charms.mysql.v0.mysql.MySQLGetClusterEndpointsError: Failed to get endpoints from cluster status
unit-mysql-0: 01:41:04 ERROR unit.mysql/0.juju-log Failed to get cluster status for test_cluster
unit-mysql-1: 01:41:07 ERROR unit.mysql/1.juju-log Failed to get cluster status for test_cluster
unit-mysql-1: 01:41:07 ERROR unit.mysql/1.juju-log Failed to get cluster members
Traceback (most recent call last):
  File "/var/lib/juju/agents/unit-mysql-1/charm/src/relations/mysql_provider.py", line 163, in _update_endpoints
    rw_endpoints, ro_endpoints, _ = self.charm._mysql.get_cluster_endpoints()
  File "/var/lib/juju/agents/unit-mysql-1/charm/lib/charms/tempo_k8s/v1/charm_tracing.py", line 647, in wrapped_function
    return callable(*args, **kwargs)  # type: ignore
  File "/var/lib/juju/agents/unit-mysql-1/charm/lib/charms/mysql/v0/mysql.py", line 1945, in get_cluster_endpoints
    raise MySQLGetClusterEndpointsError("Failed to get endpoints from cluster status")
charms.mysql.v0.mysql.MySQLGetClusterEndpointsError: Failed to get endpoints from cluster status
unit-mysql-0: 01:42:57 ERROR unit.mysql/0.juju-log Failed to flush GENERAL LOGS logs.
Traceback (most recent call last):
  File "/var/lib/juju/agents/unit-mysql-0/charm/src/mysql_vm_helpers.py", line 711, in _run_mysqlsh_script
    return subprocess.check_output(
  File "/usr/lib/python3.10/subprocess.py", line 421, in check_output
    return run(*popenargs, stdout=PIPE, timeout=timeout, check=True,
  File "/usr/lib/python3.10/subprocess.py", line 505, in run
    stdout, stderr = process.communicate(input, timeout=timeout)
  File "/usr/lib/python3.10/subprocess.py", line 1154, in communicate
    stdout, stderr = self._communicate(input, endtime, timeout)
  File "/usr/lib/python3.10/subprocess.py", line 2022, in _communicate
    self._check_timeout(endtime, orig_timeout, stdout, stderr)
  File "/usr/lib/python3.10/subprocess.py", line 1198, in _check_timeout
    raise TimeoutExpired(
subprocess.TimeoutExpired: Command '['charmed-mysql.mysqlsh', '--no-wizard', '--python', '-f', '/var/snap/charmed-mysql/common/tmpa4223mra']' timed out after 50 seconds

During handling of the above exception, another exception occurred:

Traceback (most recent call last):
  File "/var/lib/juju/agents/unit-mysql-0/charm/lib/charms/mysql/v0/mysql.py", line 3191, in flush_mysql_logs
    self._run_mysqlsh_script("\n".join(flush_logs_commands), timeout=50)
  File "/var/lib/juju/agents/unit-mysql-0/charm/lib/charms/tempo_k8s/v1/charm_tracing.py", line 647, in wrapped_function
    return callable(*args, **kwargs)  # type: ignore
  File "/var/lib/juju/agents/unit-mysql-0/charm/src/mysql_vm_helpers.py", line 715, in _run_mysqlsh_script
    raise MySQLClientError
charms.mysql.v0.mysql.MySQLClientError
machine-1: 01:44:59 ERROR juju.worker.dependency "api-caller" manifold worker returned unexpected error: api connection broken unexpectedly
machine-1: 01:45:02 ERROR juju.worker.dependency "api-caller" manifold worker returned unexpected error: [c14a3e] "machine-1" cannot open api: unable to connect to API: dial tcp 10.24.109.109:17070: connect: network is unreachable
machine-1: 01:45:06 ERROR juju.worker.dependency "api-caller" manifold worker returned unexpected error: [c14a3e] "machine-1" cannot open api: unable to connect to API: dial tcp 10.24.109.109:17070: connect: network is unreachable
machine-1: 01:45:11 ERROR juju.worker.dependency "api-caller" manifold worker returned unexpected error: [c14a3e] "machine-1" cannot open api: unable to connect to API: dial tcp 10.24.109.109:17070: connect: network is unreachable
unit-mysql-1: 01:45:42 ERROR unit.mysql/1.juju-log Failed to get cluster status for test_cluster
unit-mysql-0: 01:48:05 ERROR unit.mysql/0.juju-log Failed to flush ERROR LOGS logs.
Traceback (most recent call last):
  File "/var/lib/juju/agents/unit-mysql-0/charm/src/mysql_vm_helpers.py", line 711, in _run_mysqlsh_script
    return subprocess.check_output(
  File "/usr/lib/python3.10/subprocess.py", line 421, in check_output
    return run(*popenargs, stdout=PIPE, timeout=timeout, check=True,
  File "/usr/lib/python3.10/subprocess.py", line 526, in run
    raise CalledProcessError(retcode, process.args,
subprocess.CalledProcessError: Command '['charmed-mysql.mysqlsh', '--no-wizard', '--python', '-f', '/var/snap/charmed-mysql/common/tmp5msiyt3o']' returned non-zero exit status 1.

During handling of the above exception, another exception occurred:

Traceback (most recent call last):
  File "/var/lib/juju/agents/unit-mysql-0/charm/lib/charms/mysql/v0/mysql.py", line 3191, in flush_mysql_logs
    self._run_mysqlsh_script("\n".join(flush_logs_commands), timeout=50)
  File "/var/lib/juju/agents/unit-mysql-0/charm/lib/charms/tempo_k8s/v1/charm_tracing.py", line 647, in wrapped_function
    return callable(*args, **kwargs)  # type: ignore
  File "/var/lib/juju/agents/unit-mysql-0/charm/src/mysql_vm_helpers.py", line 715, in _run_mysqlsh_script
    raise MySQLClientError
charms.mysql.v0.mysql.MySQLClientError
unit-mysql-2: 01:50:09 ERROR unit.mysql/2.juju-log Failed to flush GENERAL LOGS logs.
Traceback (most recent call last):
  File "/var/lib/juju/agents/unit-mysql-2/charm/src/mysql_vm_helpers.py", line 711, in _run_mysqlsh_script
    return subprocess.check_output(
  File "/usr/lib/python3.10/subprocess.py", line 421, in check_output
    return run(*popenargs, stdout=PIPE, timeout=timeout, check=True,
  File "/usr/lib/python3.10/subprocess.py", line 526, in run
    raise CalledProcessError(retcode, process.args,
subprocess.CalledProcessError: Command '['charmed-mysql.mysqlsh', '--no-wizard', '--python', '-f', '/var/snap/charmed-mysql/common/tmp4gesb2fr']' returned non-zero exit status 1.

During handling of the above exception, another exception occurred:

Traceback (most recent call last):
  File "/var/lib/juju/agents/unit-mysql-2/charm/lib/charms/mysql/v0/mysql.py", line 3191, in flush_mysql_logs
    self._run_mysqlsh_script("\n".join(flush_logs_commands), timeout=50)
  File "/var/lib/juju/agents/unit-mysql-2/charm/lib/charms/tempo_k8s/v1/charm_tracing.py", line 647, in wrapped_function
    return callable(*args, **kwargs)  # type: ignore
  File "/var/lib/juju/agents/unit-mysql-2/charm/src/mysql_vm_helpers.py", line 715, in _run_mysqlsh_script
    raise MySQLClientError
charms.mysql.v0.mysql.MySQLClientError
unit-mysql-0: 01:53:59 ERROR unit.mysql/0.juju-log Failed to get member state: mysqld daemon is down
unit-mysql-0: 01:54:09 ERROR unit.mysql/0.juju-log Failed to get member state: mysqld daemon is down
unit-mysql-0: 01:54:19 ERROR unit.mysql/0.juju-log Failed to get member state: mysqld daemon is down
unit-mysql-0: 01:54:21 ERROR unit.mysql/0.juju-log Failed to get cluster status for test_cluster
unit-mysql-0: 01:54:21 ERROR unit.mysql/0.juju-log Failed to get cluster members
Traceback (most recent call last):
  File "/var/lib/juju/agents/unit-mysql-0/charm/src/relations/mysql_provider.py", line 163, in _update_endpoints
    rw_endpoints, ro_endpoints, _ = self.charm._mysql.get_cluster_endpoints()
  File "/var/lib/juju/agents/unit-mysql-0/charm/lib/charms/tempo_k8s/v1/charm_tracing.py", line 647, in wrapped_function
    return callable(*args, **kwargs)  # type: ignore
  File "/var/lib/juju/agents/unit-mysql-0/charm/lib/charms/mysql/v0/mysql.py", line 1945, in get_cluster_endpoints
    raise MySQLGetClusterEndpointsError("Failed to get endpoints from cluster status")
charms.mysql.v0.mysql.MySQLGetClusterEndpointsError: Failed to get endpoints from cluster status

[32mINFO    [0m pytest_operator.plugin:plugin.py:862 Forgetting main...