[32mINFO    [0m integration.high_availability.conftest:conftest.py:23 Clearing continuous writes
[32mINFO    [0m integration.high_availability.conftest:conftest.py:26 Starting continuous writes
[32mINFO    [0m integration.helpers:helpers.py:475 Retrieving primary unit
[32mINFO    [0m integration.high_availability.high_availability_helpers:high_availability_helpers.py:361 Ensure continuous writes are incrementing
[32mINFO    [0m integration.helpers:helpers.py:475 Retrieving primary unit
[32mINFO    [0m integration.high_availability.test_self_healing:test_self_healing.py:393 Stopping server on unit mysql/2
[32mINFO    [0m integration.high_availability.test_self_healing:test_self_healing.py:396 Removing data directory
[32mINFO    [0m integration.high_availability.test_self_healing:test_self_healing.py:412 Purge binlogs on unit mysql/0
[32mINFO    [0m integration.high_availability.test_self_healing:test_self_healing.py:412 Purge binlogs on unit mysql/1
[32mINFO    [0m integration.high_availability.test_self_healing:test_self_healing.py:420 Waiting unit to enter in maintenance.
[32mINFO    [0m integration.high_availability.test_self_healing:test_self_healing.py:427 Waiting unit to be back online.
[32mINFO    [0m integration.helpers:helpers.py:475 Retrieving primary unit
[32mINFO    [0m integration.high_availability.test_self_healing:test_self_healing.py:439 Check if instance in cluster
[32mINFO    [0m integration.high_availability.high_availability_helpers:high_availability_helpers.py:361 Ensure continuous writes are incrementing
[32mINFO    [0m integration.helpers:helpers.py:475 Retrieving primary unit
[32mINFO    [0m integration.helpers:helpers.py:475 Retrieving primary unit
[32mINFO    [0m integration.helpers:helpers.py:475 Retrieving primary unit
[32mINFO    [0m integration.high_availability.conftest:conftest.py:31 Clearing continuous writes
[32mINFO    [0m pytest_operator.plugin:plugin.py:790 Model status:

Model  Controller           Cloud/Region         Version  SLA          Timestamp
test   localhost-localhost  localhost/localhost  3.4.3    unsupported  01:48:19Z

App             Version          Status  Scale  Charm           Channel      Rev  Exposed  Message
mysql           8.0.36-0ubun...  active      3  mysql                          0  no       
mysql-test-app  0.0.2            active      1  mysql-test-app  latest/edge   37  no       

Unit               Workload  Agent  Machine  Public address  Ports           Message
mysql-test-app/0*  active    idle   3        10.254.143.72                   
mysql/0*           active    idle   0        10.254.143.69   3306,33060/tcp  
mysql/1            active    idle   1        10.254.143.179  3306,33060/tcp  Primary
mysql/2            active    idle   2        10.254.143.153  3306,33060/tcp  

Machine  State    Address         Inst id        Base          AZ  Message
0        started  10.254.143.69   juju-48b1fc-0  ubuntu@22.04      Running
1        started  10.254.143.179  juju-48b1fc-1  ubuntu@22.04      Running
2        started  10.254.143.153  juju-48b1fc-2  ubuntu@22.04      Running
3        started  10.254.143.72   juju-48b1fc-3  ubuntu@22.04      Running

[32mINFO    [0m pytest_operator.plugin:plugin.py:796 Juju error logs:

machine-0: 01:30:27 ERROR juju.worker.dependency "broker-tracker" manifold worker returned unexpected error: no container types determined
machine-0: 01:30:27 ERROR juju.worker.dependency "lxd-container-provisioner" manifold worker returned unexpected error: container types not yet available
machine-0: 01:30:27 ERROR juju.worker.dependency "kvm-container-provisioner" manifold worker returned unexpected error: container types not yet available
unit-mysql-0: 01:30:27 ERROR juju.worker.meterstatus error running "meter-status-changed": charm missing from disk
machine-2: 01:30:28 ERROR juju.worker.dependency "kvm-container-provisioner" manifold worker returned unexpected error: container types not yet available
machine-2: 01:30:28 ERROR juju.worker.dependency "broker-tracker" manifold worker returned unexpected error: no container types determined
machine-2: 01:30:28 ERROR juju.worker.dependency "lxd-container-provisioner" manifold worker returned unexpected error: container types not yet available
unit-mysql-2: 01:30:28 ERROR juju.worker.meterstatus error running "meter-status-changed": charm missing from disk
machine-1: 01:30:30 ERROR juju.worker.dependency "lxd-container-provisioner" manifold worker returned unexpected error: container types not yet available
machine-1: 01:30:30 ERROR juju.worker.dependency "kvm-container-provisioner" manifold worker returned unexpected error: container types not yet available
machine-1: 01:30:30 ERROR juju.worker.dependency "broker-tracker" manifold worker returned unexpected error: no container types determined
unit-mysql-1: 01:30:30 ERROR juju.worker.meterstatus error running "meter-status-changed": charm missing from disk
machine-3: 01:33:27 ERROR juju.worker.dependency "lxd-container-provisioner" manifold worker returned unexpected error: container types not yet available
machine-3: 01:33:27 ERROR juju.worker.dependency "kvm-container-provisioner" manifold worker returned unexpected error: container types not yet available
machine-3: 01:33:27 ERROR juju.worker.dependency "broker-tracker" manifold worker returned unexpected error: no container types determined
unit-mysql-test-app-0: 01:33:27 ERROR juju.worker.meterstatus error running "meter-status-changed": charm missing from disk
unit-mysql-0: 01:34:50 ERROR unit.mysql/0.juju-log Failed to get cluster status for test_cluster
unit-mysql-0: 01:34:58 ERROR unit.mysql/0.juju-log Failed to get cluster status for test_cluster
unit-mysql-0: 01:34:58 ERROR unit.mysql/0.juju-log Failed to get cluster members
Traceback (most recent call last):
  File "/var/lib/juju/agents/unit-mysql-0/charm/src/relations/mysql_provider.py", line 163, in _update_endpoints
    rw_endpoints, ro_endpoints, _ = self.charm._mysql.get_cluster_endpoints()
  File "/var/lib/juju/agents/unit-mysql-0/charm/lib/charms/tempo_k8s/v1/charm_tracing.py", line 544, in wrapped_function
    return callable(*args, **kwargs)  # type: ignore
  File "/var/lib/juju/agents/unit-mysql-0/charm/lib/charms/mysql/v0/mysql.py", line 1946, in get_cluster_endpoints
    raise MySQLGetClusterEndpointsError("Failed to get endpoints from cluster status")
charms.mysql.v0.mysql.MySQLGetClusterEndpointsError: Failed to get endpoints from cluster status
unit-mysql-0: 01:35:00 ERROR unit.mysql/0.juju-log Failed to get cluster status for test_cluster
unit-mysql-0: 01:35:08 ERROR unit.mysql/0.juju-log Failed to get cluster status for test_cluster
unit-mysql-0: 01:35:08 ERROR unit.mysql/0.juju-log Failed to get cluster members
Traceback (most recent call last):
  File "/var/lib/juju/agents/unit-mysql-0/charm/src/relations/mysql_provider.py", line 163, in _update_endpoints
    rw_endpoints, ro_endpoints, _ = self.charm._mysql.get_cluster_endpoints()
  File "/var/lib/juju/agents/unit-mysql-0/charm/lib/charms/tempo_k8s/v1/charm_tracing.py", line 544, in wrapped_function
    return callable(*args, **kwargs)  # type: ignore
  File "/var/lib/juju/agents/unit-mysql-0/charm/lib/charms/mysql/v0/mysql.py", line 1946, in get_cluster_endpoints
    raise MySQLGetClusterEndpointsError("Failed to get endpoints from cluster status")
charms.mysql.v0.mysql.MySQLGetClusterEndpointsError: Failed to get endpoints from cluster status
unit-mysql-0: 01:35:09 ERROR unit.mysql/0.juju-log Failed to get cluster status for test_cluster
unit-mysql-0: 01:35:15 ERROR unit.mysql/0.juju-log Failed to get cluster status for test_cluster
unit-mysql-0: 01:35:15 ERROR unit.mysql/0.juju-log Failed to get cluster members
Traceback (most recent call last):
  File "/var/lib/juju/agents/unit-mysql-0/charm/src/relations/mysql_provider.py", line 163, in _update_endpoints
    rw_endpoints, ro_endpoints, _ = self.charm._mysql.get_cluster_endpoints()
  File "/var/lib/juju/agents/unit-mysql-0/charm/lib/charms/tempo_k8s/v1/charm_tracing.py", line 544, in wrapped_function
    return callable(*args, **kwargs)  # type: ignore
  File "/var/lib/juju/agents/unit-mysql-0/charm/lib/charms/mysql/v0/mysql.py", line 1946, in get_cluster_endpoints
    raise MySQLGetClusterEndpointsError("Failed to get endpoints from cluster status")
charms.mysql.v0.mysql.MySQLGetClusterEndpointsError: Failed to get endpoints from cluster status
machine-2: 01:37:57 ERROR juju.worker.dependency "api-caller" manifold worker returned unexpected error: api connection broken unexpectedly
machine-2: 01:38:00 ERROR juju.worker.dependency "api-caller" manifold worker returned unexpected error: [e9b66a] "machine-2" cannot open api: unable to connect to API: dial tcp 10.254.143.113:17070: connect: network is unreachable
unit-mysql-1: 01:41:02 ERROR unit.mysql/1.juju-log Failed to flush ERROR LOGS logs.
Traceback (most recent call last):
  File "/var/lib/juju/agents/unit-mysql-1/charm/src/mysql_vm_helpers.py", line 685, in _run_mysqlsh_script
    return subprocess.check_output(
  File "/usr/lib/python3.10/subprocess.py", line 421, in check_output
    return run(*popenargs, stdout=PIPE, timeout=timeout, check=True,
  File "/usr/lib/python3.10/subprocess.py", line 526, in run
    raise CalledProcessError(retcode, process.args,
subprocess.CalledProcessError: Command '['charmed-mysql.mysqlsh', '--no-wizard', '--python', '-f', '/var/snap/charmed-mysql/common/tmpe64eb_mi']' returned non-zero exit status 1.

During handling of the above exception, another exception occurred:

Traceback (most recent call last):
  File "/var/lib/juju/agents/unit-mysql-1/charm/lib/charms/mysql/v0/mysql.py", line 3139, in flush_mysql_logs
    self._run_mysqlsh_script("\n".join(flush_logs_commands), timeout=50)
  File "/var/lib/juju/agents/unit-mysql-1/charm/lib/charms/tempo_k8s/v1/charm_tracing.py", line 544, in wrapped_function
    return callable(*args, **kwargs)  # type: ignore
  File "/var/lib/juju/agents/unit-mysql-1/charm/src/mysql_vm_helpers.py", line 689, in _run_mysqlsh_script
    raise MySQLClientError(e.stderr)
charms.mysql.v0.mysql.MySQLClientError: b'Traceback (most recent call last):\n  File "<string>", line 1, in <module>\nmysqlsh.DBError: MySQL Error (2013): Shell.connect: Lost connection to MySQL server at \'reading initial communication packet\', system error: 104\n'
unit-mysql-1: 01:41:03 ERROR unit.mysql/1.juju-log Failed to flush GENERAL LOGS logs.
Traceback (most recent call last):
  File "/var/lib/juju/agents/unit-mysql-1/charm/src/mysql_vm_helpers.py", line 685, in _run_mysqlsh_script
    return subprocess.check_output(
  File "/usr/lib/python3.10/subprocess.py", line 421, in check_output
    return run(*popenargs, stdout=PIPE, timeout=timeout, check=True,
  File "/usr/lib/python3.10/subprocess.py", line 526, in run
    raise CalledProcessError(retcode, process.args,
subprocess.CalledProcessError: Command '['charmed-mysql.mysqlsh', '--no-wizard', '--python', '-f', '/var/snap/charmed-mysql/common/tmpvdiw_2ww']' returned non-zero exit status 1.

During handling of the above exception, another exception occurred:

Traceback (most recent call last):
  File "/var/lib/juju/agents/unit-mysql-1/charm/lib/charms/mysql/v0/mysql.py", line 3139, in flush_mysql_logs
    self._run_mysqlsh_script("\n".join(flush_logs_commands), timeout=50)
  File "/var/lib/juju/agents/unit-mysql-1/charm/lib/charms/tempo_k8s/v1/charm_tracing.py", line 544, in wrapped_function
    return callable(*args, **kwargs)  # type: ignore
  File "/var/lib/juju/agents/unit-mysql-1/charm/src/mysql_vm_helpers.py", line 689, in _run_mysqlsh_script
    raise MySQLClientError(e.stderr)
charms.mysql.v0.mysql.MySQLClientError: b'Traceback (most recent call last):\n  File "<string>", line 1, in <module>\nmysqlsh.DBError: MySQL Error (2003): Shell.connect: Can\'t connect to MySQL server on \'juju-48b1fc-1.lxd:3306\' (111)\n'
unit-mysql-1: 01:42:03 ERROR unit.mysql/1.juju-log Failed to flush ERROR LOGS logs.
Traceback (most recent call last):
  File "/var/lib/juju/agents/unit-mysql-1/charm/src/mysql_vm_helpers.py", line 685, in _run_mysqlsh_script
    return subprocess.check_output(
  File "/usr/lib/python3.10/subprocess.py", line 421, in check_output
    return run(*popenargs, stdout=PIPE, timeout=timeout, check=True,
  File "/usr/lib/python3.10/subprocess.py", line 526, in run
    raise CalledProcessError(retcode, process.args,
subprocess.CalledProcessError: Command '['charmed-mysql.mysqlsh', '--no-wizard', '--python', '-f', '/var/snap/charmed-mysql/common/tmpngkjhd4w']' returned non-zero exit status 1.

During handling of the above exception, another exception occurred:

Traceback (most recent call last):
  File "/var/lib/juju/agents/unit-mysql-1/charm/lib/charms/mysql/v0/mysql.py", line 3139, in flush_mysql_logs
    self._run_mysqlsh_script("\n".join(flush_logs_commands), timeout=50)
  File "/var/lib/juju/agents/unit-mysql-1/charm/lib/charms/tempo_k8s/v1/charm_tracing.py", line 544, in wrapped_function
    return callable(*args, **kwargs)  # type: ignore
  File "/var/lib/juju/agents/unit-mysql-1/charm/src/mysql_vm_helpers.py", line 689, in _run_mysqlsh_script
    raise MySQLClientError(e.stderr)
charms.mysql.v0.mysql.MySQLClientError: b'Traceback (most recent call last):\n  File "<string>", line 1, in <module>\nmysqlsh.DBError: MySQL Error (2003): Shell.connect: Can\'t connect to MySQL server on \'juju-48b1fc-1.lxd:3306\' (111)\n'
unit-mysql-0: 01:43:02 ERROR unit.mysql/0.juju-log Failed to flush ERROR LOGS logs.
Traceback (most recent call last):
  File "/var/lib/juju/agents/unit-mysql-0/charm/src/mysql_vm_helpers.py", line 685, in _run_mysqlsh_script
    return subprocess.check_output(
  File "/usr/lib/python3.10/subprocess.py", line 421, in check_output
    return run(*popenargs, stdout=PIPE, timeout=timeout, check=True,
  File "/usr/lib/python3.10/subprocess.py", line 526, in run
    raise CalledProcessError(retcode, process.args,
subprocess.CalledProcessError: Command '['charmed-mysql.mysqlsh', '--no-wizard', '--python', '-f', '/var/snap/charmed-mysql/common/tmpmdfpi8fn']' returned non-zero exit status 1.

During handling of the above exception, another exception occurred:

Traceback (most recent call last):
  File "/var/lib/juju/agents/unit-mysql-0/charm/lib/charms/mysql/v0/mysql.py", line 3139, in flush_mysql_logs
    self._run_mysqlsh_script("\n".join(flush_logs_commands), timeout=50)
  File "/var/lib/juju/agents/unit-mysql-0/charm/lib/charms/tempo_k8s/v1/charm_tracing.py", line 544, in wrapped_function
    return callable(*args, **kwargs)  # type: ignore
  File "/var/lib/juju/agents/unit-mysql-0/charm/src/mysql_vm_helpers.py", line 689, in _run_mysqlsh_script
    raise MySQLClientError(e.stderr)
charms.mysql.v0.mysql.MySQLClientError: b'Traceback (most recent call last):\n  File "<string>", line 1, in <module>\nmysqlsh.DBError: MySQL Error (2003): Shell.connect: Can\'t connect to MySQL server on \'juju-48b1fc-0.lxd:3306\' (111)\n'
unit-mysql-1: 01:43:02 ERROR unit.mysql/1.juju-log Failed to flush ERROR LOGS logs.
Traceback (most recent call last):
  File "/var/lib/juju/agents/unit-mysql-1/charm/src/mysql_vm_helpers.py", line 685, in _run_mysqlsh_script
    return subprocess.check_output(
  File "/usr/lib/python3.10/subprocess.py", line 421, in check_output
    return run(*popenargs, stdout=PIPE, timeout=timeout, check=True,
  File "/usr/lib/python3.10/subprocess.py", line 526, in run
    raise CalledProcessError(retcode, process.args,
subprocess.CalledProcessError: Command '['charmed-mysql.mysqlsh', '--no-wizard', '--python', '-f', '/var/snap/charmed-mysql/common/tmpp9l8z5h2']' returned non-zero exit status 1.

During handling of the above exception, another exception occurred:

Traceback (most recent call last):
  File "/var/lib/juju/agents/unit-mysql-1/charm/lib/charms/mysql/v0/mysql.py", line 3139, in flush_mysql_logs
    self._run_mysqlsh_script("\n".join(flush_logs_commands), timeout=50)
  File "/var/lib/juju/agents/unit-mysql-1/charm/lib/charms/tempo_k8s/v1/charm_tracing.py", line 544, in wrapped_function
    return callable(*args, **kwargs)  # type: ignore
  File "/var/lib/juju/agents/unit-mysql-1/charm/src/mysql_vm_helpers.py", line 689, in _run_mysqlsh_script
    raise MySQLClientError(e.stderr)
charms.mysql.v0.mysql.MySQLClientError: b'Traceback (most recent call last):\n  File "<string>", line 1, in <module>\nmysqlsh.DBError: MySQL Error (2003): Shell.connect: Can\'t connect to MySQL server on \'juju-48b1fc-1.lxd:3306\' (111)\n'
unit-mysql-0: 01:43:03 ERROR unit.mysql/0.juju-log Failed to flush GENERAL LOGS logs.
Traceback (most recent call last):
  File "/var/lib/juju/agents/unit-mysql-0/charm/src/mysql_vm_helpers.py", line 685, in _run_mysqlsh_script
    return subprocess.check_output(
  File "/usr/lib/python3.10/subprocess.py", line 421, in check_output
    return run(*popenargs, stdout=PIPE, timeout=timeout, check=True,
  File "/usr/lib/python3.10/subprocess.py", line 526, in run
    raise CalledProcessError(retcode, process.args,
subprocess.CalledProcessError: Command '['charmed-mysql.mysqlsh', '--no-wizard', '--python', '-f', '/var/snap/charmed-mysql/common/tmpruddurmg']' returned non-zero exit status 1.

During handling of the above exception, another exception occurred:

Traceback (most recent call last):
  File "/var/lib/juju/agents/unit-mysql-0/charm/lib/charms/mysql/v0/mysql.py", line 3139, in flush_mysql_logs
    self._run_mysqlsh_script("\n".join(flush_logs_commands), timeout=50)
  File "/var/lib/juju/agents/unit-mysql-0/charm/lib/charms/tempo_k8s/v1/charm_tracing.py", line 544, in wrapped_function
    return callable(*args, **kwargs)  # type: ignore
  File "/var/lib/juju/agents/unit-mysql-0/charm/src/mysql_vm_helpers.py", line 689, in _run_mysqlsh_script
    raise MySQLClientError(e.stderr)
charms.mysql.v0.mysql.MySQLClientError: b'Traceback (most recent call last):\n  File "<string>", line 1, in <module>\nmysqlsh.DBError: MySQL Error (2003): Shell.connect: Can\'t connect to MySQL server on \'juju-48b1fc-0.lxd:3306\' (111)\n'
unit-mysql-1: 01:43:03 ERROR unit.mysql/1.juju-log Failed to flush GENERAL LOGS logs.
Traceback (most recent call last):
  File "/var/lib/juju/agents/unit-mysql-1/charm/src/mysql_vm_helpers.py", line 685, in _run_mysqlsh_script
    return subprocess.check_output(
  File "/usr/lib/python3.10/subprocess.py", line 421, in check_output
    return run(*popenargs, stdout=PIPE, timeout=timeout, check=True,
  File "/usr/lib/python3.10/subprocess.py", line 526, in run
    raise CalledProcessError(retcode, process.args,
subprocess.CalledProcessError: Command '['charmed-mysql.mysqlsh', '--no-wizard', '--python', '-f', '/var/snap/charmed-mysql/common/tmprte2mvly']' returned non-zero exit status 1.

During handling of the above exception, another exception occurred:

Traceback (most recent call last):
  File "/var/lib/juju/agents/unit-mysql-1/charm/lib/charms/mysql/v0/mysql.py", line 3139, in flush_mysql_logs
    self._run_mysqlsh_script("\n".join(flush_logs_commands), timeout=50)
  File "/var/lib/juju/agents/unit-mysql-1/charm/lib/charms/tempo_k8s/v1/charm_tracing.py", line 544, in wrapped_function
    return callable(*args, **kwargs)  # type: ignore
  File "/var/lib/juju/agents/unit-mysql-1/charm/src/mysql_vm_helpers.py", line 689, in _run_mysqlsh_script
    raise MySQLClientError(e.stderr)
charms.mysql.v0.mysql.MySQLClientError: b'Traceback (most recent call last):\n  File "<string>", line 1, in <module>\nmysqlsh.DBError: MySQL Error (2003): Shell.connect: Can\'t connect to MySQL server on \'juju-48b1fc-1.lxd:3306\' (111)\n'
unit-mysql-2: 01:44:03 ERROR unit.mysql/2.juju-log Failed to flush ERROR LOGS logs.
Traceback (most recent call last):
  File "/var/lib/juju/agents/unit-mysql-2/charm/src/mysql_vm_helpers.py", line 685, in _run_mysqlsh_script
    return subprocess.check_output(
  File "/usr/lib/python3.10/subprocess.py", line 421, in check_output
    return run(*popenargs, stdout=PIPE, timeout=timeout, check=True,
  File "/usr/lib/python3.10/subprocess.py", line 526, in run
    raise CalledProcessError(retcode, process.args,
subprocess.CalledProcessError: Command '['charmed-mysql.mysqlsh', '--no-wizard', '--python', '-f', '/var/snap/charmed-mysql/common/tmp4y_8yx5p']' returned non-zero exit status 1.

During handling of the above exception, another exception occurred:

Traceback (most recent call last):
  File "/var/lib/juju/agents/unit-mysql-2/charm/lib/charms/mysql/v0/mysql.py", line 3139, in flush_mysql_logs
    self._run_mysqlsh_script("\n".join(flush_logs_commands), timeout=50)
  File "/var/lib/juju/agents/unit-mysql-2/charm/lib/charms/tempo_k8s/v1/charm_tracing.py", line 544, in wrapped_function
    return callable(*args, **kwargs)  # type: ignore
  File "/var/lib/juju/agents/unit-mysql-2/charm/src/mysql_vm_helpers.py", line 689, in _run_mysqlsh_script
    raise MySQLClientError(e.stderr)
charms.mysql.v0.mysql.MySQLClientError: b'Traceback (most recent call last):\n  File "<string>", line 1, in <module>\nmysqlsh.DBError: MySQL Error (2003): Shell.connect: Can\'t connect to MySQL server on \'juju-48b1fc-2.lxd:3306\' (111)\n'
unit-mysql-1: 01:44:03 ERROR unit.mysql/1.juju-log Failed to flush ERROR LOGS logs.
Traceback (most recent call last):
  File "/var/lib/juju/agents/unit-mysql-1/charm/src/mysql_vm_helpers.py", line 685, in _run_mysqlsh_script
    return subprocess.check_output(
  File "/usr/lib/python3.10/subprocess.py", line 421, in check_output
    return run(*popenargs, stdout=PIPE, timeout=timeout, check=True,
  File "/usr/lib/python3.10/subprocess.py", line 526, in run
    raise CalledProcessError(retcode, process.args,
subprocess.CalledProcessError: Command '['charmed-mysql.mysqlsh', '--no-wizard', '--python', '-f', '/var/snap/charmed-mysql/common/tmpyzuur08x']' returned non-zero exit status 1.

During handling of the above exception, another exception occurred:

Traceback (most recent call last):
  File "/var/lib/juju/agents/unit-mysql-1/charm/lib/charms/mysql/v0/mysql.py", line 3139, in flush_mysql_logs
    self._run_mysqlsh_script("\n".join(flush_logs_commands), timeout=50)
  File "/var/lib/juju/agents/unit-mysql-1/charm/lib/charms/tempo_k8s/v1/charm_tracing.py", line 544, in wrapped_function
    return callable(*args, **kwargs)  # type: ignore
  File "/var/lib/juju/agents/unit-mysql-1/charm/src/mysql_vm_helpers.py", line 689, in _run_mysqlsh_script
    raise MySQLClientError(e.stderr)
charms.mysql.v0.mysql.MySQLClientError: b'Traceback (most recent call last):\n  File "<string>", line 1, in <module>\nmysqlsh.DBError: MySQL Error (2003): Shell.connect: Can\'t connect to MySQL server on \'juju-48b1fc-1.lxd:3306\' (111)\n'
unit-mysql-0: 01:44:03 ERROR unit.mysql/0.juju-log Failed to flush ERROR LOGS logs.
Traceback (most recent call last):
  File "/var/lib/juju/agents/unit-mysql-0/charm/src/mysql_vm_helpers.py", line 685, in _run_mysqlsh_script
    return subprocess.check_output(
  File "/usr/lib/python3.10/subprocess.py", line 421, in check_output
    return run(*popenargs, stdout=PIPE, timeout=timeout, check=True,
  File "/usr/lib/python3.10/subprocess.py", line 526, in run
    raise CalledProcessError(retcode, process.args,
subprocess.CalledProcessError: Command '['charmed-mysql.mysqlsh', '--no-wizard', '--python', '-f', '/var/snap/charmed-mysql/common/tmpi_yzvj7t']' returned non-zero exit status 1.

During handling of the above exception, another exception occurred:

Traceback (most recent call last):
  File "/var/lib/juju/agents/unit-mysql-0/charm/lib/charms/mysql/v0/mysql.py", line 3139, in flush_mysql_logs
    self._run_mysqlsh_script("\n".join(flush_logs_commands), timeout=50)
  File "/var/lib/juju/agents/unit-mysql-0/charm/lib/charms/tempo_k8s/v1/charm_tracing.py", line 544, in wrapped_function
    return callable(*args, **kwargs)  # type: ignore
  File "/var/lib/juju/agents/unit-mysql-0/charm/src/mysql_vm_helpers.py", line 689, in _run_mysqlsh_script
    raise MySQLClientError(e.stderr)
charms.mysql.v0.mysql.MySQLClientError: b'Traceback (most recent call last):\n  File "<string>", line 1, in <module>\nmysqlsh.DBError: MySQL Error (2003): Shell.connect: Can\'t connect to MySQL server on \'juju-48b1fc-0.lxd:3306\' (111)\n'
unit-mysql-0: 01:44:34 ERROR unit.mysql/0.juju-log Failed to get cluster status for test_cluster
unit-mysql-0: 01:44:34 ERROR unit.mysql/0.juju-log Failed to get cluster members
Traceback (most recent call last):
  File "/var/lib/juju/agents/unit-mysql-0/charm/src/relations/mysql_provider.py", line 163, in _update_endpoints
    rw_endpoints, ro_endpoints, _ = self.charm._mysql.get_cluster_endpoints()
  File "/var/lib/juju/agents/unit-mysql-0/charm/lib/charms/tempo_k8s/v1/charm_tracing.py", line 544, in wrapped_function
    return callable(*args, **kwargs)  # type: ignore
  File "/var/lib/juju/agents/unit-mysql-0/charm/lib/charms/mysql/v0/mysql.py", line 1946, in get_cluster_endpoints
    raise MySQLGetClusterEndpointsError("Failed to get endpoints from cluster status")
charms.mysql.v0.mysql.MySQLGetClusterEndpointsError: Failed to get endpoints from cluster status
unit-mysql-2: 01:47:02 ERROR unit.mysql/2.juju-log Failed to get member state: mysqld daemon is down
unit-mysql-2: 01:47:13 ERROR unit.mysql/2.juju-log Failed to get member state: mysqld daemon is down
unit-mysql-2: 01:47:23 ERROR unit.mysql/2.juju-log Failed to get member state: mysqld daemon is down

[32mINFO    [0m pytest_operator.plugin:plugin.py:862 Forgetting main...