[32mINFO    [0m integration.high_availability.conftest:conftest.py:23 Clearing continuous writes
[32mINFO    [0m integration.high_availability.conftest:conftest.py:26 Starting continuous writes
[32mINFO    [0m integration.helpers:helpers.py:475 Retrieving primary unit
[32mINFO    [0m integration.high_availability.high_availability_helpers:high_availability_helpers.py:361 Ensure continuous writes are incrementing
[32mINFO    [0m integration.helpers:helpers.py:475 Retrieving primary unit
[32mINFO    [0m integration.high_availability.test_self_healing:test_self_healing.py:393 Stopping server on unit mysql/0
[32mINFO    [0m integration.high_availability.test_self_healing:test_self_healing.py:396 Removing data directory
[32mINFO    [0m integration.high_availability.test_self_healing:test_self_healing.py:412 Purge binlogs on unit mysql/1
[32mINFO    [0m integration.high_availability.test_self_healing:test_self_healing.py:412 Purge binlogs on unit mysql/2
[32mINFO    [0m integration.high_availability.test_self_healing:test_self_healing.py:420 Waiting unit to enter in maintenance.
[32mINFO    [0m integration.high_availability.test_self_healing:test_self_healing.py:427 Waiting unit to be back online.
[32mINFO    [0m integration.helpers:helpers.py:475 Retrieving primary unit
[32mINFO    [0m integration.high_availability.test_self_healing:test_self_healing.py:439 Check if instance in cluster
[32mINFO    [0m integration.high_availability.high_availability_helpers:high_availability_helpers.py:361 Ensure continuous writes are incrementing
[32mINFO    [0m integration.helpers:helpers.py:475 Retrieving primary unit
[32mINFO    [0m integration.helpers:helpers.py:475 Retrieving primary unit
[32mINFO    [0m integration.helpers:helpers.py:475 Retrieving primary unit
[32mINFO    [0m integration.high_availability.conftest:conftest.py:31 Clearing continuous writes
[32mINFO    [0m pytest_operator.plugin:plugin.py:790 Model status:

Model  Controller           Cloud/Region         Version  SLA          Timestamp
test   localhost-localhost  localhost/localhost  3.1.8    unsupported  01:59:27Z

App             Version          Status  Scale  Charm           Channel      Rev  Exposed  Message
mysql           8.0.36-0ubun...  active      3  mysql                          0  no       
mysql-test-app  0.0.2            active      1  mysql-test-app  latest/edge   37  no       Last written value=4641

Unit               Workload  Agent  Machine  Public address  Ports           Message
mysql-test-app/0*  active    idle   3        10.112.97.217                   Last written value=4641
mysql/0            active    idle   0        10.112.97.218   3306,33060/tcp  
mysql/1            active    idle   1        10.112.97.130   3306,33060/tcp  
mysql/2*           active    idle   2        10.112.97.55    3306,33060/tcp  Primary

Machine  State    Address        Inst id        Base          AZ  Message
0        started  10.112.97.218  juju-5640f7-0  ubuntu@22.04      Running
1        started  10.112.97.130  juju-5640f7-1  ubuntu@22.04      Running
2        started  10.112.97.55   juju-5640f7-2  ubuntu@22.04      Running
3        started  10.112.97.217  juju-5640f7-3  ubuntu@22.04      Running

[32mINFO    [0m pytest_operator.plugin:plugin.py:796 Juju error logs:

machine-2: 01:40:02 ERROR juju.worker.dependency "lxd-container-provisioner" manifold worker returned unexpected error: container types not yet available
machine-2: 01:40:02 ERROR juju.worker.dependency "kvm-container-provisioner" manifold worker returned unexpected error: container types not yet available
machine-2: 01:40:02 ERROR juju.worker.dependency "broker-tracker" manifold worker returned unexpected error: no container types determined
unit-mysql-2: 01:40:02 ERROR juju.worker.meterstatus error running "meter-status-changed": charm missing from disk
machine-0: 01:40:10 ERROR juju.worker.dependency "broker-tracker" manifold worker returned unexpected error: no container types determined
machine-0: 01:40:10 ERROR juju.worker.dependency "lxd-container-provisioner" manifold worker returned unexpected error: container types not yet available
machine-0: 01:40:10 ERROR juju.worker.dependency "kvm-container-provisioner" manifold worker returned unexpected error: container types not yet available
unit-mysql-0: 01:40:11 ERROR juju.worker.meterstatus error running "meter-status-changed": charm missing from disk
machine-1: 01:40:14 ERROR juju.worker.dependency "lxd-container-provisioner" manifold worker returned unexpected error: container types not yet available
machine-1: 01:40:14 ERROR juju.worker.dependency "kvm-container-provisioner" manifold worker returned unexpected error: container types not yet available
machine-1: 01:40:14 ERROR juju.worker.dependency "broker-tracker" manifold worker returned unexpected error: no container types determined
unit-mysql-1: 01:40:14 ERROR juju.worker.meterstatus error running "meter-status-changed": charm missing from disk
machine-3: 01:43:37 ERROR juju.worker.dependency "broker-tracker" manifold worker returned unexpected error: no container types determined
machine-3: 01:43:37 ERROR juju.worker.dependency "lxd-container-provisioner" manifold worker returned unexpected error: container types not yet available
machine-3: 01:43:37 ERROR juju.worker.dependency "kvm-container-provisioner" manifold worker returned unexpected error: container types not yet available
unit-mysql-test-app-0: 01:43:37 ERROR juju.worker.meterstatus error running "meter-status-changed": charm missing from disk
unit-mysql-0: 01:44:55 ERROR unit.mysql/0.juju-log Failed to get cluster status for test_cluster
unit-mysql-0: 01:45:02 ERROR unit.mysql/0.juju-log Failed to get cluster status for test_cluster
unit-mysql-2: 01:45:07 ERROR unit.mysql/2.juju-log Failed to get cluster status for test_cluster
unit-mysql-2: 01:45:07 ERROR unit.mysql/2.juju-log Failed to get cluster members
Traceback (most recent call last):
  File "/var/lib/juju/agents/unit-mysql-2/charm/src/relations/mysql_provider.py", line 163, in _update_endpoints
    rw_endpoints, ro_endpoints, _ = self.charm._mysql.get_cluster_endpoints()
  File "/var/lib/juju/agents/unit-mysql-2/charm/lib/charms/mysql/v0/mysql.py", line 1900, in get_cluster_endpoints
    raise MySQLGetClusterEndpointsError("Failed to get endpoints from cluster status")
charms.mysql.v0.mysql.MySQLGetClusterEndpointsError: Failed to get endpoints from cluster status
unit-mysql-0: 01:45:10 ERROR unit.mysql/0.juju-log Failed to get cluster status for test_cluster
unit-mysql-2: 01:45:15 ERROR unit.mysql/2.juju-log Failed to get cluster status for test_cluster
unit-mysql-2: 01:45:15 ERROR unit.mysql/2.juju-log Failed to get cluster members
Traceback (most recent call last):
  File "/var/lib/juju/agents/unit-mysql-2/charm/src/relations/mysql_provider.py", line 163, in _update_endpoints
    rw_endpoints, ro_endpoints, _ = self.charm._mysql.get_cluster_endpoints()
  File "/var/lib/juju/agents/unit-mysql-2/charm/lib/charms/mysql/v0/mysql.py", line 1900, in get_cluster_endpoints
    raise MySQLGetClusterEndpointsError("Failed to get endpoints from cluster status")
charms.mysql.v0.mysql.MySQLGetClusterEndpointsError: Failed to get endpoints from cluster status
machine-0: 01:48:40 ERROR juju.worker.dependency "api-caller" manifold worker returned unexpected error: api connection broken unexpectedly
unit-mysql-0: 01:48:58 ERROR unit.mysql/0.juju-log Failed to get cluster status for test_cluster
unit-mysql-2: 01:52:02 ERROR unit.mysql/2.juju-log Failed to flush ERROR LOGS logs.
Traceback (most recent call last):
  File "/var/lib/juju/agents/unit-mysql-2/charm/src/mysql_vm_helpers.py", line 678, in _run_mysqlsh_script
    return subprocess.check_output(
  File "/usr/lib/python3.10/subprocess.py", line 421, in check_output
    return run(*popenargs, stdout=PIPE, timeout=timeout, check=True,
  File "/usr/lib/python3.10/subprocess.py", line 526, in run
    raise CalledProcessError(retcode, process.args,
subprocess.CalledProcessError: Command '['charmed-mysql.mysqlsh', '--no-wizard', '--python', '-f', '/var/snap/charmed-mysql/common/tmpiaypubal']' returned non-zero exit status 1.

During handling of the above exception, another exception occurred:

Traceback (most recent call last):
  File "/var/lib/juju/agents/unit-mysql-2/charm/lib/charms/mysql/v0/mysql.py", line 3089, in flush_mysql_logs
    self._run_mysqlsh_script("\n".join(flush_logs_commands), timeout=50)
  File "/var/lib/juju/agents/unit-mysql-2/charm/src/mysql_vm_helpers.py", line 682, in _run_mysqlsh_script
    raise MySQLClientError(e.stderr)
charms.mysql.v0.mysql.MySQLClientError: b'Traceback (most recent call last):\n  File "<string>", line 1, in <module>\nmysqlsh.DBError: MySQL Error (2003): Shell.connect: Can\'t connect to MySQL server on \'juju-5640f7-2.lxd:3306\' (111)\n'
unit-mysql-2: 01:52:03 ERROR unit.mysql/2.juju-log Failed to flush GENERAL LOGS logs.
Traceback (most recent call last):
  File "/var/lib/juju/agents/unit-mysql-2/charm/src/mysql_vm_helpers.py", line 678, in _run_mysqlsh_script
    return subprocess.check_output(
  File "/usr/lib/python3.10/subprocess.py", line 421, in check_output
    return run(*popenargs, stdout=PIPE, timeout=timeout, check=True,
  File "/usr/lib/python3.10/subprocess.py", line 526, in run
    raise CalledProcessError(retcode, process.args,
subprocess.CalledProcessError: Command '['charmed-mysql.mysqlsh', '--no-wizard', '--python', '-f', '/var/snap/charmed-mysql/common/tmp3zhi0kau']' returned non-zero exit status 1.

During handling of the above exception, another exception occurred:

Traceback (most recent call last):
  File "/var/lib/juju/agents/unit-mysql-2/charm/lib/charms/mysql/v0/mysql.py", line 3089, in flush_mysql_logs
    self._run_mysqlsh_script("\n".join(flush_logs_commands), timeout=50)
  File "/var/lib/juju/agents/unit-mysql-2/charm/src/mysql_vm_helpers.py", line 682, in _run_mysqlsh_script
    raise MySQLClientError(e.stderr)
charms.mysql.v0.mysql.MySQLClientError: b'Traceback (most recent call last):\n  File "<string>", line 1, in <module>\nmysqlsh.DBError: MySQL Error (2003): Shell.connect: Can\'t connect to MySQL server on \'juju-5640f7-2.lxd:3306\' (111)\n'
unit-mysql-2: 01:54:02 ERROR unit.mysql/2.juju-log Failed to flush ERROR LOGS logs.
Traceback (most recent call last):
  File "/var/lib/juju/agents/unit-mysql-2/charm/src/mysql_vm_helpers.py", line 678, in _run_mysqlsh_script
    return subprocess.check_output(
  File "/usr/lib/python3.10/subprocess.py", line 421, in check_output
    return run(*popenargs, stdout=PIPE, timeout=timeout, check=True,
  File "/usr/lib/python3.10/subprocess.py", line 526, in run
    raise CalledProcessError(retcode, process.args,
subprocess.CalledProcessError: Command '['charmed-mysql.mysqlsh', '--no-wizard', '--python', '-f', '/var/snap/charmed-mysql/common/tmpua7aup8x']' returned non-zero exit status 1.

During handling of the above exception, another exception occurred:

Traceback (most recent call last):
  File "/var/lib/juju/agents/unit-mysql-2/charm/lib/charms/mysql/v0/mysql.py", line 3089, in flush_mysql_logs
    self._run_mysqlsh_script("\n".join(flush_logs_commands), timeout=50)
  File "/var/lib/juju/agents/unit-mysql-2/charm/src/mysql_vm_helpers.py", line 682, in _run_mysqlsh_script
    raise MySQLClientError(e.stderr)
charms.mysql.v0.mysql.MySQLClientError: b'Traceback (most recent call last):\n  File "<string>", line 1, in <module>\nmysqlsh.DBError: MySQL Error (2003): Shell.connect: Can\'t connect to MySQL server on \'juju-5640f7-2.lxd:3306\' (111)\n'
unit-mysql-1: 01:54:03 ERROR unit.mysql/1.juju-log Failed to flush ERROR LOGS logs.
Traceback (most recent call last):
  File "/var/lib/juju/agents/unit-mysql-1/charm/src/mysql_vm_helpers.py", line 678, in _run_mysqlsh_script
    return subprocess.check_output(
  File "/usr/lib/python3.10/subprocess.py", line 421, in check_output
    return run(*popenargs, stdout=PIPE, timeout=timeout, check=True,
  File "/usr/lib/python3.10/subprocess.py", line 526, in run
    raise CalledProcessError(retcode, process.args,
subprocess.CalledProcessError: Command '['charmed-mysql.mysqlsh', '--no-wizard', '--python', '-f', '/var/snap/charmed-mysql/common/tmpcuwjhz2x']' returned non-zero exit status 1.

During handling of the above exception, another exception occurred:

Traceback (most recent call last):
  File "/var/lib/juju/agents/unit-mysql-1/charm/lib/charms/mysql/v0/mysql.py", line 3089, in flush_mysql_logs
    self._run_mysqlsh_script("\n".join(flush_logs_commands), timeout=50)
  File "/var/lib/juju/agents/unit-mysql-1/charm/src/mysql_vm_helpers.py", line 682, in _run_mysqlsh_script
    raise MySQLClientError(e.stderr)
charms.mysql.v0.mysql.MySQLClientError: b'Traceback (most recent call last):\n  File "<string>", line 1, in <module>\nmysqlsh.DBError: MySQL Error (2003): Shell.connect: Can\'t connect to MySQL server on \'juju-5640f7-1.lxd:3306\' (111)\n'
unit-mysql-2: 01:54:04 ERROR unit.mysql/2.juju-log Failed to flush GENERAL LOGS logs.
Traceback (most recent call last):
  File "/var/lib/juju/agents/unit-mysql-2/charm/src/mysql_vm_helpers.py", line 678, in _run_mysqlsh_script
    return subprocess.check_output(
  File "/usr/lib/python3.10/subprocess.py", line 421, in check_output
    return run(*popenargs, stdout=PIPE, timeout=timeout, check=True,
  File "/usr/lib/python3.10/subprocess.py", line 526, in run
    raise CalledProcessError(retcode, process.args,
subprocess.CalledProcessError: Command '['charmed-mysql.mysqlsh', '--no-wizard', '--python', '-f', '/var/snap/charmed-mysql/common/tmp0o9doquw']' returned non-zero exit status 1.

During handling of the above exception, another exception occurred:

Traceback (most recent call last):
  File "/var/lib/juju/agents/unit-mysql-2/charm/lib/charms/mysql/v0/mysql.py", line 3089, in flush_mysql_logs
    self._run_mysqlsh_script("\n".join(flush_logs_commands), timeout=50)
  File "/var/lib/juju/agents/unit-mysql-2/charm/src/mysql_vm_helpers.py", line 682, in _run_mysqlsh_script
    raise MySQLClientError(e.stderr)
charms.mysql.v0.mysql.MySQLClientError: b'Traceback (most recent call last):\n  File "<string>", line 1, in <module>\nmysqlsh.DBError: MySQL Error (2003): Shell.connect: Can\'t connect to MySQL server on \'juju-5640f7-2.lxd:3306\' (111)\n'
unit-mysql-1: 01:54:04 ERROR unit.mysql/1.juju-log Failed to flush GENERAL LOGS logs.
Traceback (most recent call last):
  File "/var/lib/juju/agents/unit-mysql-1/charm/src/mysql_vm_helpers.py", line 678, in _run_mysqlsh_script
    return subprocess.check_output(
  File "/usr/lib/python3.10/subprocess.py", line 421, in check_output
    return run(*popenargs, stdout=PIPE, timeout=timeout, check=True,
  File "/usr/lib/python3.10/subprocess.py", line 526, in run
    raise CalledProcessError(retcode, process.args,
subprocess.CalledProcessError: Command '['charmed-mysql.mysqlsh', '--no-wizard', '--python', '-f', '/var/snap/charmed-mysql/common/tmpbi1opopo']' returned non-zero exit status 1.

During handling of the above exception, another exception occurred:

Traceback (most recent call last):
  File "/var/lib/juju/agents/unit-mysql-1/charm/lib/charms/mysql/v0/mysql.py", line 3089, in flush_mysql_logs
    self._run_mysqlsh_script("\n".join(flush_logs_commands), timeout=50)
  File "/var/lib/juju/agents/unit-mysql-1/charm/src/mysql_vm_helpers.py", line 682, in _run_mysqlsh_script
    raise MySQLClientError(e.stderr)
charms.mysql.v0.mysql.MySQLClientError: b'Traceback (most recent call last):\n  File "<string>", line 1, in <module>\nmysqlsh.DBError: MySQL Error (2003): Shell.connect: Can\'t connect to MySQL server on \'juju-5640f7-1.lxd:3306\' (111)\n'
unit-mysql-0: 01:57:02 ERROR unit.mysql/0.juju-log Failed to flush ERROR LOGS logs.
Traceback (most recent call last):
  File "/var/lib/juju/agents/unit-mysql-0/charm/src/mysql_vm_helpers.py", line 678, in _run_mysqlsh_script
    return subprocess.check_output(
  File "/usr/lib/python3.10/subprocess.py", line 421, in check_output
    return run(*popenargs, stdout=PIPE, timeout=timeout, check=True,
  File "/usr/lib/python3.10/subprocess.py", line 526, in run
    raise CalledProcessError(retcode, process.args,
subprocess.CalledProcessError: Command '['charmed-mysql.mysqlsh', '--no-wizard', '--python', '-f', '/var/snap/charmed-mysql/common/tmp2_y09vvd']' returned non-zero exit status 1.

During handling of the above exception, another exception occurred:

Traceback (most recent call last):
  File "/var/lib/juju/agents/unit-mysql-0/charm/lib/charms/mysql/v0/mysql.py", line 3089, in flush_mysql_logs
    self._run_mysqlsh_script("\n".join(flush_logs_commands), timeout=50)
  File "/var/lib/juju/agents/unit-mysql-0/charm/src/mysql_vm_helpers.py", line 682, in _run_mysqlsh_script
    raise MySQLClientError(e.stderr)
charms.mysql.v0.mysql.MySQLClientError: b'Traceback (most recent call last):\n  File "<string>", line 1, in <module>\nmysqlsh.DBError: MySQL Error (2003): Shell.connect: Can\'t connect to MySQL server on \'juju-5640f7-0.lxd:3306\' (111)\n'
unit-mysql-0: 01:57:03 ERROR unit.mysql/0.juju-log Failed to flush GENERAL LOGS logs.
Traceback (most recent call last):
  File "/var/lib/juju/agents/unit-mysql-0/charm/src/mysql_vm_helpers.py", line 678, in _run_mysqlsh_script
    return subprocess.check_output(
  File "/usr/lib/python3.10/subprocess.py", line 421, in check_output
    return run(*popenargs, stdout=PIPE, timeout=timeout, check=True,
  File "/usr/lib/python3.10/subprocess.py", line 526, in run
    raise CalledProcessError(retcode, process.args,
subprocess.CalledProcessError: Command '['charmed-mysql.mysqlsh', '--no-wizard', '--python', '-f', '/var/snap/charmed-mysql/common/tmpql52vhmo']' returned non-zero exit status 1.

During handling of the above exception, another exception occurred:

Traceback (most recent call last):
  File "/var/lib/juju/agents/unit-mysql-0/charm/lib/charms/mysql/v0/mysql.py", line 3089, in flush_mysql_logs
    self._run_mysqlsh_script("\n".join(flush_logs_commands), timeout=50)
  File "/var/lib/juju/agents/unit-mysql-0/charm/src/mysql_vm_helpers.py", line 682, in _run_mysqlsh_script
    raise MySQLClientError(e.stderr)
charms.mysql.v0.mysql.MySQLClientError: b'Traceback (most recent call last):\n  File "<string>", line 1, in <module>\nmysqlsh.DBError: MySQL Error (2003): Shell.connect: Can\'t connect to MySQL server on \'juju-5640f7-0.lxd:3306\' (111)\n'
unit-mysql-0: 01:58:02 ERROR unit.mysql/0.juju-log Failed to flush ERROR LOGS logs.
Traceback (most recent call last):
  File "/var/lib/juju/agents/unit-mysql-0/charm/src/mysql_vm_helpers.py", line 678, in _run_mysqlsh_script
    return subprocess.check_output(
  File "/usr/lib/python3.10/subprocess.py", line 421, in check_output
    return run(*popenargs, stdout=PIPE, timeout=timeout, check=True,
  File "/usr/lib/python3.10/subprocess.py", line 526, in run
    raise CalledProcessError(retcode, process.args,
subprocess.CalledProcessError: Command '['charmed-mysql.mysqlsh', '--no-wizard', '--python', '-f', '/var/snap/charmed-mysql/common/tmppn4z_k07']' returned non-zero exit status 1.

During handling of the above exception, another exception occurred:

Traceback (most recent call last):
  File "/var/lib/juju/agents/unit-mysql-0/charm/lib/charms/mysql/v0/mysql.py", line 3089, in flush_mysql_logs
    self._run_mysqlsh_script("\n".join(flush_logs_commands), timeout=50)
  File "/var/lib/juju/agents/unit-mysql-0/charm/src/mysql_vm_helpers.py", line 682, in _run_mysqlsh_script
    raise MySQLClientError(e.stderr)
charms.mysql.v0.mysql.MySQLClientError: b'Traceback (most recent call last):\n  File "<string>", line 1, in <module>\nmysqlsh.DBError: MySQL Error (2003): Shell.connect: Can\'t connect to MySQL server on \'juju-5640f7-0.lxd:3306\' (111)\n'
unit-mysql-0: 01:58:05 ERROR unit.mysql/0.juju-log Failed to get member state: mysqld daemon is down
unit-mysql-0: 01:58:16 ERROR unit.mysql/0.juju-log Failed to get member state: mysqld daemon is down
unit-mysql-0: 01:58:26 ERROR unit.mysql/0.juju-log Failed to get member state: mysqld daemon is down

[32mINFO    [0m pytest_operator.plugin:plugin.py:862 Forgetting main...