[33mWARNING [0m juju.client.connection:connection.py:858 unexpected facade SSHServer received from the controller
[32mINFO    [0m pytest_operator.plugin:plugin.py:734 Connecting to existing model concierge-lxd:testing on unspecified cloud
[33mWARNING [0m juju.client.connection:connection.py:858 unexpected facade SSHServer received from the controller
[33mWARNING [0m juju.client.connection:connection.py:858 unexpected facade SSHSession received from the controller
[33mWARNING [0m juju.client.connection:connection.py:858 unexpected facade SSHTunneler received from the controller
[33mWARNING [0m juju.client.connection:connection.py:858 unexpected facade SSHServer received from the controller
[32mINFO    [0m integration.high_availability.conftest:conftest.py:48 Deploying mysql and scaling to 3 units
[32mINFO    [0m juju.model:model.py:2284 Deploying local:mysql-0
[32mINFO    [0m juju.model:model.py:3211 Waiting for model:
  mysql/0 [allocating] waiting: waiting for machine
  mysql/1 [allocating] waiting: waiting for machine
  mysql/2 [allocating] waiting: waiting for machine
[32mINFO    [0m juju.model:model.py:3211 Waiting for model:
  mysql/0 [allocating] waiting: waiting for machine
  mysql/1 [allocating] waiting: waiting for machine
  mysql/2 [allocating] waiting: waiting for machine
[32mINFO    [0m juju.model:model.py:3211 Waiting for model:
  mysql/0 [allocating] waiting: waiting for machine
  mysql/1 [allocating] waiting: waiting for machine
  mysql/2 [allocating] waiting: waiting for machine
[32mINFO    [0m juju.model:model.py:3211 Waiting for model:
  mysql/0 [allocating] waiting: agent initialising
  mysql/1 [allocating] waiting: waiting for machine
  mysql/2 [allocating] waiting: waiting for machine
[32mINFO    [0m juju.model:model.py:3211 Waiting for model:
  mysql/0 [executing] maintenance: Installing MySQL
  mysql/1 [allocating] waiting: waiting for machine
  mysql/2 [allocating] waiting: waiting for machine
[32mINFO    [0m juju.model:model.py:3211 Waiting for model:
  mysql/0 [executing] maintenance: Setting up cluster node
  mysql/1 [allocating] waiting: waiting for machine
  mysql/2 [allocating] waiting: waiting for machine
[32mINFO    [0m juju.model:model.py:3211 Waiting for model:
  mysql/0 [idle] active: Primary
  mysql/1 [executing] maintenance: Installing MySQL
  mysql/2 [allocating] waiting: waiting for machine
[32mINFO    [0m juju.model:model.py:3211 Waiting for model:
  mysql/0 [idle] active: Primary
  mysql/1 [executing] maintenance: Setting up cluster node
  mysql/2 [executing] maintenance: Installing MySQL
[32mINFO    [0m juju.model:model.py:3211 Waiting for model:
  mysql/0 [idle] active: Primary
  mysql/1 [executing] maintenance: joining the cluster
  mysql/2 [executing] waiting: Waiting to join the cluster
[32mINFO    [0m juju.model:model.py:3211 Waiting for model:
  mysql/0 [executing] active: Primary
  mysql/1 [executing] active: 
  mysql/2 [executing] active: 
[32mINFO    [0m integration.high_availability.conftest:conftest.py:51 Deploying mysql-test-app
[32mINFO    [0m juju.model:model.py:2284 Deploying ch:amd64/jammy/mysql-test-app-73
[32mINFO    [0m juju.model:model.py:3211 Waiting for model:
  mysql-test-app/0 [allocating] waiting: waiting for machine
[32mINFO    [0m juju.model:model.py:3211 Waiting for model:
  mysql-test-app/0 [allocating] waiting: waiting for machine
[32mINFO    [0m juju.model:model.py:3211 Waiting for model:
  mysql-test-app/0 [allocating] waiting: waiting for machine
[32mINFO    [0m integration.high_availability.conftest:conftest.py:54 Relating mysql with mysql-test-app
[33mWARNING [0m juju.model:model.py:1666 relate is deprecated and will be removed. Use integrate instead.
[32mINFO    [0m juju.model:model.py:3211 Waiting for model:
  mysql/0 [idle] active: Primary
  mysql/1 [idle] active: 
  mysql/2 [idle] active: 
  mysql-test-app/0 [idle] waiting: 
[32mINFO    [0m juju.model:model.py:3211 Waiting for model:
  mysql/0 [idle] active: Primary
  mysql/1 [idle] active: 
  mysql/2 [idle] active: 
[32mINFO    [0m integration.high_availability.conftest:conftest.py:29 Clearing continuous writes
[32mINFO    [0m integration.high_availability.conftest:conftest.py:32 Starting continuous writes
[32mINFO    [0m integration.high_availability.high_availability_helpers:high_availability_helpers.py:342 Ensure continuous writes are incrementing
[32mINFO    [0m integration.helpers:helpers.py:482 Retrieving primary unit
[32mINFO    [0m integration.high_availability.high_availability_helpers:high_availability_helpers.py:367 max_written_value=522 on unit mysql/0
[32mINFO    [0m integration.high_availability.high_availability_helpers:high_availability_helpers.py:367 max_written_value=525 on unit mysql/1
[32mINFO    [0m integration.high_availability.high_availability_helpers:high_availability_helpers.py:367 max_written_value=530 on unit mysql/2
[32mINFO    [0m integration.helpers:helpers.py:482 Retrieving primary unit
[32mINFO    [0m integration.high_availability.high_availability_helpers:high_availability_helpers.py:88 Ensure 3 units are online
[32mINFO    [0m integration.high_availability.test_self_healing_process_killed:test_self_healing_process_killed.py:51 Killing process id 6779
[32mINFO    [0m integration.high_availability.test_self_healing_process_killed:test_self_healing_process_killed.py:56 New process id is 15665
[32mINFO    [0m integration.high_availability.high_availability_helpers:high_availability_helpers.py:342 Ensure continuous writes are incrementing
[32mINFO    [0m integration.helpers:helpers.py:482 Retrieving primary unit
[32mINFO    [0m integration.high_availability.high_availability_helpers:high_availability_helpers.py:367 max_written_value=1058 on unit mysql/0
[32mINFO    [0m integration.high_availability.high_availability_helpers:high_availability_helpers.py:367 max_written_value=1058 on unit mysql/0
[32mINFO    [0m integration.high_availability.high_availability_helpers:high_availability_helpers.py:367 max_written_value=1576 on unit mysql/0
[32mINFO    [0m integration.high_availability.high_availability_helpers:high_availability_helpers.py:367 max_written_value=1586 on unit mysql/1
[32mINFO    [0m integration.high_availability.high_availability_helpers:high_availability_helpers.py:367 max_written_value=1593 on unit mysql/2
[32mINFO    [0m integration.helpers:helpers.py:482 Retrieving primary unit
[32mINFO    [0m integration.helpers:helpers.py:482 Retrieving primary unit
[32mINFO    [0m integration.high_availability.conftest:conftest.py:37 Clearing continuous writes
[32mINFO    [0m pytest_operator.plugin:plugin.py:862 Model status:

Model    Controller     Cloud/Region         Version  SLA          Timestamp
testing  concierge-lxd  localhost/localhost  3.6.8    unsupported  01:52:54Z

App             Version          Status  Scale  Charm           Channel      Rev  Exposed  Message
mysql           8.0.42-0ubun...  active      3  mysql                          0  no       
mysql-test-app  0.0.2            active      1  mysql-test-app  latest/edge   73  no       Last written value=1295

Unit               Workload  Agent  Machine  Public address  Ports           Message
mysql-test-app/0*  active    idle   3        10.197.232.24                   Last written value=1295
mysql/0*           active    idle   0        10.197.232.114  3306,33060/tcp  
mysql/1            active    idle   1        10.197.232.151  3306,33060/tcp  Primary
mysql/2            active    idle   2        10.197.232.72                   

Machine  State    Address         Inst id        Base          AZ  Message
0        started  10.197.232.114  juju-0c9b38-0  ubuntu@22.04      Running
1        started  10.197.232.151  juju-0c9b38-1  ubuntu@22.04      Running
2        started  10.197.232.72   juju-0c9b38-2  ubuntu@22.04      Running
3        started  10.197.232.24   juju-0c9b38-3  ubuntu@22.04      Running

[32mINFO    [0m pytest_operator.plugin:plugin.py:868 Juju error logs:

machine-0: 01:45:43 ERROR juju.worker.dependency "lxd-container-provisioner" manifold worker returned unexpected error: container types not yet available
machine-0: 01:45:43 ERROR juju.worker.dependency "kvm-container-provisioner" manifold worker returned unexpected error: container types not yet available
unit-mysql-0: 01:45:43 ERROR juju.worker.meterstatus error running "meter-status-changed": charm missing from disk
machine-1: 01:47:12 ERROR juju.worker.dependency "lxd-container-provisioner" manifold worker returned unexpected error: container types not yet available
machine-1: 01:47:12 ERROR juju.worker.dependency "kvm-container-provisioner" manifold worker returned unexpected error: container types not yet available
unit-mysql-1: 01:47:12 ERROR juju.worker.meterstatus error running "meter-status-changed": charm missing from disk
machine-2: 01:47:23 ERROR juju.worker.dependency "lxd-container-provisioner" manifold worker returned unexpected error: container types not yet available
machine-2: 01:47:23 ERROR juju.worker.dependency "kvm-container-provisioner" manifold worker returned unexpected error: container types not yet available
unit-mysql-2: 01:47:23 ERROR juju.worker.meterstatus error running "meter-status-changed": charm missing from disk
machine-3: 01:50:29 ERROR juju.worker.dependency "lxd-container-provisioner" manifold worker returned unexpected error: container types not yet available
machine-3: 01:50:29 ERROR juju.worker.dependency "kvm-container-provisioner" manifold worker returned unexpected error: container types not yet available
unit-mysql-test-app-0: 01:50:29 ERROR juju.worker.meterstatus error running "meter-status-changed": charm missing from disk
unit-mysql-0: 01:51:42 ERROR unit.mysql/0.juju-log Failed to execute mysql-shell command
Traceback (most recent call last):
  File "/var/lib/juju/agents/unit-mysql-0/charm/src/mysql_vm_helpers.py", line 779, in _run_mysqlsh_script
    output = subprocess.check_output(
  File "/usr/lib/python3.10/subprocess.py", line 421, in check_output
    return run(*popenargs, stdout=PIPE, timeout=timeout, check=True,
  File "/usr/lib/python3.10/subprocess.py", line 526, in run
    raise CalledProcessError(retcode, process.args,
subprocess.CalledProcessError: Command '['charmed-mysql.mysqlsh', '--passwords-from-stdin', '--uri=serverconfig@juju-0c9b38-0.lxd:33062', '--python', '-c', "shell.options.set('useWizards', False)\nprint('###')\ncluster = dba.get_cluster('test_cluster')\nprint(cluster.status({'extended': False}))"]' returned non-zero exit status 1.
unit-mysql-0: 01:51:42 ERROR unit.mysql/0.juju-log Failed to get cluster status for test_cluster
unit-mysql-0: 01:51:51 ERROR unit.mysql/0.juju-log Failed to execute mysql-shell command
Traceback (most recent call last):
  File "/var/lib/juju/agents/unit-mysql-0/charm/src/mysql_vm_helpers.py", line 779, in _run_mysqlsh_script
    output = subprocess.check_output(
  File "/usr/lib/python3.10/subprocess.py", line 421, in check_output
    return run(*popenargs, stdout=PIPE, timeout=timeout, check=True,
  File "/usr/lib/python3.10/subprocess.py", line 526, in run
    raise CalledProcessError(retcode, process.args,
subprocess.CalledProcessError: Command '['charmed-mysql.mysqlsh', '--passwords-from-stdin', '--uri=serverconfig@10.197.232.151:33062', '--python', '-c', "shell.options.set('useWizards', False)\nprint('###')\nshell.connect_to_primary()\nprimary_address = shell.parse_uri(session.uri)['host']\nprint(f'<PRIMARY_ADDRESS>{primary_address}</PRIMARY_ADDRESS>')"]' returned non-zero exit status 1.
unit-mysql-0: 01:51:52 ERROR unit.mysql/0.juju-log Failed to execute mysql-shell command
Traceback (most recent call last):
  File "/var/lib/juju/agents/unit-mysql-0/charm/src/mysql_vm_helpers.py", line 779, in _run_mysqlsh_script
    output = subprocess.check_output(
  File "/usr/lib/python3.10/subprocess.py", line 421, in check_output
    return run(*popenargs, stdout=PIPE, timeout=timeout, check=True,
  File "/usr/lib/python3.10/subprocess.py", line 526, in run
    raise CalledProcessError(retcode, process.args,
subprocess.CalledProcessError: Command '['charmed-mysql.mysqlsh', '--passwords-from-stdin', '--uri=serverconfig@10.197.232.72:33062', '--python', '-c', "shell.options.set('useWizards', False)\nprint('###')\nshell.connect_to_primary()\nprimary_address = shell.parse_uri(session.uri)['host']\nprint(f'<PRIMARY_ADDRESS>{primary_address}</PRIMARY_ADDRESS>')"]' returned non-zero exit status 1.
unit-mysql-0: 01:51:52 ERROR unit.mysql/0.juju-log Failed to execute mysql-shell command
Traceback (most recent call last):
  File "/var/lib/juju/agents/unit-mysql-0/charm/src/mysql_vm_helpers.py", line 779, in _run_mysqlsh_script
    output = subprocess.check_output(
  File "/usr/lib/python3.10/subprocess.py", line 421, in check_output
    return run(*popenargs, stdout=PIPE, timeout=timeout, check=True,
  File "/usr/lib/python3.10/subprocess.py", line 526, in run
    raise CalledProcessError(retcode, process.args,
subprocess.CalledProcessError: Command '['charmed-mysql.mysqlsh', '--passwords-from-stdin', '--uri=serverconfig@juju-0c9b38-0.lxd:33062', '--python', '-c', "shell.options.set('useWizards', False)\nprint('###')\nshell.connect_to_primary()\nprimary_address = shell.parse_uri(session.uri)['host']\nprint(f'<PRIMARY_ADDRESS>{primary_address}</PRIMARY_ADDRESS>')"]' returned non-zero exit status 1.
unit-mysql-0: 01:51:53 ERROR unit.mysql/0.juju-log Failed to execute mysql-shell command
Traceback (most recent call last):
  File "/var/lib/juju/agents/unit-mysql-0/charm/src/mysql_vm_helpers.py", line 779, in _run_mysqlsh_script
    output = subprocess.check_output(
  File "/usr/lib/python3.10/subprocess.py", line 421, in check_output
    return run(*popenargs, stdout=PIPE, timeout=timeout, check=True,
  File "/usr/lib/python3.10/subprocess.py", line 526, in run
    raise CalledProcessError(retcode, process.args,
subprocess.CalledProcessError: Command '['charmed-mysql.mysqlsh', '--passwords-from-stdin', '--uri=serverconfig@juju-0c9b38-0.lxd:33062', '--python', '-c', "shell.options.set('useWizards', False)\nprint('###')\ncluster = dba.get_cluster('test_cluster')\nprint(cluster.status({'extended': False}))"]' returned non-zero exit status 1.
unit-mysql-0: 01:51:53 ERROR unit.mysql/0.juju-log Failed to get cluster status for test_cluster
unit-mysql-0: 01:51:54 ERROR unit.mysql/0.juju-log Failed to get cluster members
Traceback (most recent call last):
  File "/var/lib/juju/agents/unit-mysql-0/charm/src/relations/mysql_provider.py", line 163, in _update_endpoints
    rw_endpoints, ro_endpoints, _ = self.charm.get_cluster_endpoints(DB_RELATION_NAME)
  File "/var/lib/juju/agents/unit-mysql-0/charm/lib/charms/tempo_coordinator_k8s/v0/charm_tracing.py", line 1065, in wrapped_function
    return callable(*args, **kwargs)  # type: ignore
  File "/var/lib/juju/agents/unit-mysql-0/charm/lib/charms/mysql/v0/mysql.py", line 869, in get_cluster_endpoints
    raise MySQLGetClusterEndpointsError("Failed to get endpoints from cluster topology")
charms.mysql.v0.mysql.MySQLGetClusterEndpointsError: Failed to get endpoints from cluster topology
unit-mysql-0: 01:51:56 ERROR unit.mysql/0.juju-log Failed to execute mysql-shell command
Traceback (most recent call last):
  File "/var/lib/juju/agents/unit-mysql-0/charm/src/mysql_vm_helpers.py", line 779, in _run_mysqlsh_script
    output = subprocess.check_output(
  File "/usr/lib/python3.10/subprocess.py", line 421, in check_output
    return run(*popenargs, stdout=PIPE, timeout=timeout, check=True,
  File "/usr/lib/python3.10/subprocess.py", line 526, in run
    raise CalledProcessError(retcode, process.args,
subprocess.CalledProcessError: Command '['charmed-mysql.mysqlsh', '--passwords-from-stdin', '--uri=serverconfig@juju-0c9b38-0.lxd:33062', '--python', '-c', "shell.options.set('useWizards', False)\nprint('###')\ncluster = dba.get_cluster('test_cluster')\nprint(cluster.status({'extended': False}))"]' returned non-zero exit status 1.
unit-mysql-0: 01:51:56 ERROR unit.mysql/0.juju-log Failed to get cluster status for test_cluster
unit-mysql-0: 01:52:05 ERROR unit.mysql/0.juju-log Failed to execute mysql-shell command
Traceback (most recent call last):
  File "/var/lib/juju/agents/unit-mysql-0/charm/src/mysql_vm_helpers.py", line 779, in _run_mysqlsh_script
    output = subprocess.check_output(
  File "/usr/lib/python3.10/subprocess.py", line 421, in check_output
    return run(*popenargs, stdout=PIPE, timeout=timeout, check=True,
  File "/usr/lib/python3.10/subprocess.py", line 526, in run
    raise CalledProcessError(retcode, process.args,
subprocess.CalledProcessError: Command '['charmed-mysql.mysqlsh', '--passwords-from-stdin', '--uri=serverconfig@10.197.232.151:33062', '--python', '-c', "shell.options.set('useWizards', False)\nprint('###')\ncluster = dba.get_cluster('test_cluster')\ncluster.rejoin_instance('mysql-0')"]' returned non-zero exit status 1.
unit-mysql-0: 01:52:05 ERROR unit.mysql/0.juju-log Failed to rejoin instance mysql-0 to cluster test_cluster
unit-mysql-0: 01:52:10 ERROR unit.mysql/0.juju-log Failed to execute mysql-shell command
Traceback (most recent call last):
  File "/var/lib/juju/agents/unit-mysql-0/charm/src/mysql_vm_helpers.py", line 779, in _run_mysqlsh_script
    output = subprocess.check_output(
  File "/usr/lib/python3.10/subprocess.py", line 421, in check_output
    return run(*popenargs, stdout=PIPE, timeout=timeout, check=True,
  File "/usr/lib/python3.10/subprocess.py", line 526, in run
    raise CalledProcessError(retcode, process.args,
subprocess.CalledProcessError: Command '['charmed-mysql.mysqlsh', '--passwords-from-stdin', '--uri=serverconfig@10.197.232.151:33062', '--python', '-c', "shell.options.set('useWizards', False)\nprint('###')\ncluster = dba.get_cluster('test_cluster')\nshell.options['dba.restartWaitTimeout'] = 3600\ncluster.add_instance('clusteradmin@10.197.232.114', {'password': '*****', 'label': 'mysql-0', 'recoveryMethod': 'auto'})"]' returned non-zero exit status 1.

During handling of the above exception, another exception occurred:

Traceback (most recent call last):
  File "/var/lib/juju/agents/unit-mysql-0/charm/lib/charms/mysql/v0/mysql.py", line 1995, in add_instance_to_cluster
    self._run_mysqlsh_script(
  File "/var/lib/juju/agents/unit-mysql-0/charm/lib/charms/tempo_coordinator_k8s/v0/charm_tracing.py", line 1065, in wrapped_function
    return callable(*args, **kwargs)  # type: ignore
  File "/var/lib/juju/agents/unit-mysql-0/charm/src/mysql_vm_helpers.py", line 794, in _run_mysqlsh_script
    raise MySQLClientError
charms.mysql.v0.mysql.MySQLClientError

During handling of the above exception, another exception occurred:

Traceback (most recent call last):
  File "/var/lib/juju/agents/unit-mysql-0/charm/src/mysql_vm_helpers.py", line 779, in _run_mysqlsh_script
    output = subprocess.check_output(
  File "/usr/lib/python3.10/subprocess.py", line 421, in check_output
    return run(*popenargs, stdout=PIPE, timeout=timeout, check=True,
  File "/usr/lib/python3.10/subprocess.py", line 526, in run
    raise CalledProcessError(retcode, process.args,
subprocess.CalledProcessError: Command '['charmed-mysql.mysqlsh', '--passwords-from-stdin', '--uri=serverconfig@10.197.232.151:33062', '--python', '-c', "shell.options.set('useWizards', False)\nprint('###')\ncluster = dba.get_cluster('test_cluster')\nshell.options['dba.restartWaitTimeout'] = 3600\ncluster.add_instance('clusteradmin@10.197.232.114', {'password': '*****', 'label': 'mysql-0', 'recoveryMethod': 'clone'})"]' returned non-zero exit status 1.
unit-mysql-0: 01:52:10 ERROR unit.mysql/0.juju-log Failed to add instance_address='10.197.232.114' to self.cluster_name='test_cluster' on self.instance_address='juju-0c9b38-0.lxd'
unit-mysql-0: 01:52:12 ERROR unit.mysql/0.juju-log Uncaught exception while in charm code:
Traceback (most recent call last):
  File "/var/lib/juju/agents/unit-mysql-0/charm/src/mysql_vm_helpers.py", line 779, in _run_mysqlsh_script
    output = subprocess.check_output(
  File "/usr/lib/python3.10/subprocess.py", line 421, in check_output
    return run(*popenargs, stdout=PIPE, timeout=timeout, check=True,
  File "/usr/lib/python3.10/subprocess.py", line 526, in run
    raise CalledProcessError(retcode, process.args,
subprocess.CalledProcessError: Command '['charmed-mysql.mysqlsh', '--passwords-from-stdin', '--uri=serverconfig@10.197.232.151:33062', '--python', '-c', "shell.options.set('useWizards', False)\nprint('###')\ncluster = dba.get_cluster('test_cluster')\nshell.options['dba.restartWaitTimeout'] = 3600\ncluster.add_instance('clusteradmin@10.197.232.114', {'password': '*****', 'label': 'mysql-0', 'recoveryMethod': 'auto'})"]' returned non-zero exit status 1.

During handling of the above exception, another exception occurred:

Traceback (most recent call last):
  File "/var/lib/juju/agents/unit-mysql-0/charm/lib/charms/mysql/v0/mysql.py", line 1995, in add_instance_to_cluster
    self._run_mysqlsh_script(
  File "/var/lib/juju/agents/unit-mysql-0/charm/lib/charms/tempo_coordinator_k8s/v0/charm_tracing.py", line 1065, in wrapped_function
    return callable(*args, **kwargs)  # type: ignore
  File "/var/lib/juju/agents/unit-mysql-0/charm/src/mysql_vm_helpers.py", line 794, in _run_mysqlsh_script
    raise MySQLClientError
charms.mysql.v0.mysql.MySQLClientError

During handling of the above exception, another exception occurred:

Traceback (most recent call last):
  File "/var/lib/juju/agents/unit-mysql-0/charm/src/mysql_vm_helpers.py", line 779, in _run_mysqlsh_script
    output = subprocess.check_output(
  File "/usr/lib/python3.10/subprocess.py", line 421, in check_output
    return run(*popenargs, stdout=PIPE, timeout=timeout, check=True,
  File "/usr/lib/python3.10/subprocess.py", line 526, in run
    raise CalledProcessError(retcode, process.args,
subprocess.CalledProcessError: Command '['charmed-mysql.mysqlsh', '--passwords-from-stdin', '--uri=serverconfig@10.197.232.151:33062', '--python', '-c', "shell.options.set('useWizards', False)\nprint('###')\ncluster = dba.get_cluster('test_cluster')\nshell.options['dba.restartWaitTimeout'] = 3600\ncluster.add_instance('clusteradmin@10.197.232.114', {'password': '*****', 'label': 'mysql-0', 'recoveryMethod': 'clone'})"]' returned non-zero exit status 1.

During handling of the above exception, another exception occurred:

Traceback (most recent call last):
  File "/var/lib/juju/agents/unit-mysql-0/charm/lib/charms/mysql/v0/mysql.py", line 1995, in add_instance_to_cluster
    self._run_mysqlsh_script(
  File "/var/lib/juju/agents/unit-mysql-0/charm/lib/charms/tempo_coordinator_k8s/v0/charm_tracing.py", line 1065, in wrapped_function
    return callable(*args, **kwargs)  # type: ignore
  File "/var/lib/juju/agents/unit-mysql-0/charm/src/mysql_vm_helpers.py", line 794, in _run_mysqlsh_script
    raise MySQLClientError
charms.mysql.v0.mysql.MySQLClientError

During handling of the above exception, another exception occurred:

Traceback (most recent call last):
  File "/var/lib/juju/agents/unit-mysql-0/charm/src/charm.py", line 1010, in <module>
    main(MySQLOperatorCharm)
  File "/var/lib/juju/agents/unit-mysql-0/charm/venv/lib/python3.10/site-packages/ops/main.py", line 551, in main
    manager.run()
  File "/var/lib/juju/agents/unit-mysql-0/charm/venv/lib/python3.10/site-packages/ops/main.py", line 530, in run
    self._emit()
  File "/var/lib/juju/agents/unit-mysql-0/charm/venv/lib/python3.10/site-packages/ops/main.py", line 519, in _emit
    _emit_charm_event(self.charm, self.dispatcher.event_name)
  File "/var/lib/juju/agents/unit-mysql-0/charm/venv/lib/python3.10/site-packages/ops/main.py", line 147, in _emit_charm_event
    event_to_emit.emit(*args, **kwargs)
  File "/var/lib/juju/agents/unit-mysql-0/charm/venv/lib/python3.10/site-packages/ops/framework.py", line 348, in emit
    framework._emit(event)
  File "/var/lib/juju/agents/unit-mysql-0/charm/venv/lib/python3.10/site-packages/ops/framework.py", line 860, in _emit
    self._reemit(event_path)
  File "/var/lib/juju/agents/unit-mysql-0/charm/venv/lib/python3.10/site-packages/ops/framework.py", line 950, in _reemit
    custom_handler(event)
  File "/var/lib/juju/agents/unit-mysql-0/charm/lib/charms/tempo_coordinator_k8s/v0/charm_tracing.py", line 1065, in wrapped_function
    return callable(*args, **kwargs)  # type: ignore
  File "/var/lib/juju/agents/unit-mysql-0/charm/src/charm.py", line 585, in _on_update_status
    if not self._handle_non_online_instance_status(state):
  File "/var/lib/juju/agents/unit-mysql-0/charm/lib/charms/tempo_coordinator_k8s/v0/charm_tracing.py", line 1065, in wrapped_function
    return callable(*args, **kwargs)  # type: ignore
  File "/var/lib/juju/agents/unit-mysql-0/charm/src/charm.py", line 478, in _handle_non_online_instance_status
    self._execute_manual_rejoin()
  File "/var/lib/juju/agents/unit-mysql-0/charm/lib/charms/tempo_coordinator_k8s/v0/charm_tracing.py", line 1065, in wrapped_function
    return callable(*args, **kwargs)  # type: ignore
  File "/var/lib/juju/agents/unit-mysql-0/charm/src/charm.py", line 522, in _execute_manual_rejoin
    self._mysql.add_instance_to_cluster(
  File "/var/lib/juju/agents/unit-mysql-0/charm/lib/charms/tempo_coordinator_k8s/v0/charm_tracing.py", line 1065, in wrapped_function
    return callable(*args, **kwargs)  # type: ignore
  File "/var/lib/juju/agents/unit-mysql-0/charm/lib/charms/mysql/v0/mysql.py", line 2013, in add_instance_to_cluster
    self.add_instance_to_cluster(
  File "/var/lib/juju/agents/unit-mysql-0/charm/lib/charms/tempo_coordinator_k8s/v0/charm_tracing.py", line 1065, in wrapped_function
    return callable(*args, **kwargs)  # type: ignore
  File "/var/lib/juju/agents/unit-mysql-0/charm/lib/charms/mysql/v0/mysql.py", line 2008, in add_instance_to_cluster
    raise MySQLAddInstanceToClusterError
charms.mysql.v0.mysql.MySQLAddInstanceToClusterError
unit-mysql-0: 01:52:12 ERROR juju.worker.uniter.operation hook "update-status" (via hook dispatching script: dispatch) failed: exit status 1

[32mINFO    [0m pytest_operator.plugin:plugin.py:947 Forgetting model main...